Workbook

Sheet 00_Huong_Dan_Nhap_Lieu
B2: HƯỚNG DẪN NHẬP LIỆU BÁO CÁO KQKD (P&L) CÁC ĐƠN VỊ & TOÀN TẬP ĐOÀN VPS
B4: 1. Cấu trúc 12 tháng: | C4: File chuẩn hóa 12 tab tương ứng từ 'Thang_01' đến 'Thang_12'. Cấu trúc 39 dòng chỉ tiêu và thứ tự cột số liệu hoàn toàn đồng nhất.
B5: 2. Số liệu chuẩn hóa đã khóa: | C5: Tháng 01, 02, 03, 04 và Tháng 07 đã được điền 100% số liệu thực tế đã qua kiểm toán đối soát chính thức của Tập đoàn VPS.
B6: 3. Quy ước màu sắc khi nhập liệu: | C6: 🟡 CÁC Ô MÀU VÀNG NHẠT (Cột D, F, G, H, I của từng bộ phận): Là các ô đơn vị cần nhập số liệu phát sinh trong tháng. ⚪ CÁC Ô MÀU TRẮNG / XÁM / XANH: Là CÔNG THỨC TỰ ĐỘNG (Tự động tính % Lãi gộp, tự động tính LNTT, tự động cộng lũy kế từ tháng trước, tự động cộng tổng công ty). Đơn vị TUYỆT ĐỐI KHÔNG SỬA CÔNG THỨC.
B7: 4. Đơn vị chỉ cần nhập đúng 5 số: | C7: Mỗi bộ phận hàng tháng chỉ cần nhập đúng 5 chỉ tiêu: (1) Doanh số tháng (Cột D) (2) Lãi gộp tháng (Cột F) (3) Hỗ trợ LG tháng (Cột G - nếu có) (4) Chi phí tháng (Cột H) (5) Thu nhập khác tháng (Cột I - nếu có)
B8: 5. Tự động tính lũy kế (YTD): | C8: Cột K, L, M, N, O, P, Q (Lũy kế các tháng) đã được cài sẵn công thức liên kết tự động cộng dồn: [Lũy kế Tháng m] = [Lũy kế Tháng m-1] + [Số liệu Tháng m]. Bạn không cần phải tự tính tay.
B9: 6. Tải lên Google Sheets: | C9: Sau khi điền hoặc cập nhật, lưu file và tải lên Google Drive -> Mở bằng Google Trang tính (Google Sheets).
B10: 7. Chia sẻ quyền xem: | C10: Nhấn 'Chia sẻ' (Share) trên Google Sheets -> Chọn 'Bất kỳ ai có đường liên kết' -> Quyền 'Người xem' (Viewer) -> Nhấn 'Sao chép đường liên kết'.
B11: 8. Quét tự động vào Dashboard: | C11: Mở Dashboard -> Mục 13. Kết Quả KD -> Nhấn 'Kết nối Google Sheet' -> Dán link và nhấn 'Lưu & Quét Dữ Liệu'. Toàn bộ các tháng (kể cả Tháng 8, 9, 10, 11, 12) sẽ tự động nạp và cập nhật lũy kế chuẩn xác 100%!

Sheet Thang_01
A1: MÁY VĂN PHÒNG HÀNG ĐẦU VIỆT NAM - TẬP ĐOÀN VPS
A2: BÁO CÁO KẾT QUẢ KINH DOANH HỢP NHẤT (P&L)
A3: TỔNG HỢP DOANH SỐ, LỢI NHUẬN TRƯỚC THUẾ • KỲ BÁO CÁO: THÁNG 01/2026 VÀ LŨY KẾ 1 THÁNG 2026
Q4: Đơn vị tính: Triệu đồng
A5: TT | B5: NỘI DUNG | C5: VỐN ĐT | D5: THÁNG 01 | K5: LŨY KẾ 1 THÁNG 2026
D6: DS | E6: % LG | F6: LG | G6: HT LG | H6: CHI PHÍ | I6: TN KHÁC | J6: LNTT | K6: DS | L6: % LG | M6: LG | N6: HT LG | O6: CHI PHÍ | P6: TN KHÁC | Q6: LNTT
A7: I | B7: MIỀN BẮC | C7: 90000 | D7: 27440 | E7: 0.29158163 | F7: 8001 | G7: 1073 | H7: 6908 | I7: 1108 | J7: 3275 | K7: 27440 | L7: 0.29158163 | M7: 8001 | N7: 1073 | O7: 6908 | P7: 1108 | Q7: 3275
A8: 1 | B8: THH (Tân Hồng Hà) | C8: 50000 | D8: 21624 | E8: 0.30729745 | F8: 6645 | G8: 0 | H8: 3881 | I8: 1 | J8: 2766 | K8: 21624 | L8: 0.30729745 | M8: 6645 | N8: 0 | O8: 3881 | P8: 1 | Q8: 2766
A9: a | B9: Khối dịch vụ kỹ thuật | D9: 2224 | E9: 0.35476619 | F9: 789 | H9: 771 | I9: 1 | J9: 18 | K9: 2224 | L9: 0.35476619 | M9: 789 | O9: 771 | P9: 1 | Q9: 18
A10: a.1 | B10: Tổ Dịch vụ | E10: 0.31 | L10: 0.31
A11: a.2 | B11: Tổ mực in | E11: 0.45 | L11: 0.45
A12: a.3 | B12: Thuê máy | E12: 0.37 | L12: 0.37
A13: a.4 | B13: Metercharge | E13: 0.6 | L13: 0.6
A14: a.5 | B14: Kinh doanh Online | E14: 0.07 | F14: 9400 | L14: 0.07 | M14: 9400
A15: b | B15: Kinh doanh tổng hợp | E15: 0.1 | H15: 139 | J15: 18 | L15: 0.1 | O15: 139 | Q15: 18
A16: c | B16: Kinh doanh bán buôn | E16: 0.07 | H16: 451 | I16: 1 | J16: -76 | L16: 0.07 | O16: 451 | P16: 1 | Q16: -76
A17: d | B17: Dự án | E17: 0.42 | H17: 2520 | J17: 2805 | L17: 0.42 | O17: 2520 | Q17: 2805
A18: 2 | B18: Việt | C18: 10000 | D18: 5393 | E18: 0.23011311 | F18: 1241 | G18: 33 | H18: 1043 | I18: 5 | J18: 236 | K18: 5393 | L18: 0.23011311 | M18: 1241 | N18: 33 | O18: 1043 | P18: 5 | Q18: 236
A19: 2.1 | B19: Thuê máy | D19: 1578 | E19: 0.56273764 | F19: 888 | H19: 687 | I19: 5 | J19: 206 | K19: 1578 | L19: 0.56273764 | M19: 888 | O19: 687 | Q19: 206
A20: 2.2 | B20: KDTH | E20: 0.09 | F20: 177 | H20: 160 | J20: 17 | K20: 1891 | L20: 0.093601269 | M20: 177 | O20: 160 | Q20: 17
A21: 2.3 | B21: KD online | E21: 0.07 | F21: 120 | H21: 165 | J21: -45 | K21: 1776 | L21: 0.067567568 | M21: 120 | O21: 165 | Q21: -45
A22: 2.4 | B22: Cửa hàng | E22: 0.38 | F22: 57 | H22: 32 | J22: 26 | K22: 149 | L22: 0.38255034 | M22: 57 | O22: 32 | Q22: 26
A23: 3 | B23: ITSS | C23: 5000 | D23: 423 | E23: 0.27186761 | F23: 115 | H23: 124 | J23: -9 | K23: 423 | L23: 0.27186761 | M23: 115 | O23: 124 | Q23: -9
A24: 4 | B24: CTY VPS | C24: 10000 | D24: 0 | E24: 0 | F24: 0 | G24: 1040 | H24: 1860 | I24: 1102 | J24: 282 | K24: 0 | L24: 0 | M24: 0 | N24: 1040 | O24: 1860 | P24: 1102 | Q24: 282
A25: 4.1 | B25: VP VPS - hoạt động KD | G25: 1040 | H25: 553 | I25: 250 | J25: 737 | N25: 1040 | O25: 553 | P25: 250 | Q25: 737
A26: 4.2 | B26: HĐ đầu tư Tài chính | H26: 1307 | I26: 852 | J26: -455 | O26: 1307 | P26: 852 | Q26: -455
A27: 5 | B27: XESCO (Xem Sơn) | C27: 15000 | D27: 10080 | E27: 0.28501984 | F27: 2873 | G27: 0 | H27: 2126 | I27: 19 | J27: 766 | K27: 10080 | L27: 0.28501984 | M27: 2873 | N27: 0 | O27: 2126 | P27: 19 | Q27: 766
A28: 5.1 | B28: Xesco - KD | D28: 6701 | E28: 0.14863453 | F28: 996 | H28: 854 | I28: 7 | J28: 149 | K28: 6701 | L28: 0.14863453 | M28: 996 | O28: 854 | P28: 7 | Q28: 149
A29: • | B29: Bán máy lẻ | D29: 665 | E29: 0.29924812 | F29: 199 | H29: 135 | I29: 1 | J29: 65 | K29: 665 | L29: 0.29924812 | M29: 199 | O29: 135 | P29: 1 | Q29: 65
A30: • | B30: KD sỉ | D30: 3408 | E30: 0.11355634 | F30: 387 | H30: 460 | I30: 4 | J30: -69 | K30: 3408 | L30: 0.11355634 | M30: 387 | O30: 460 | P30: 4 | Q30: -69
A31: • | B31: KD Online | D31: 2229 | E31: 0.054733064 | F31: 122 | H31: 77 | I31: 2 | J31: 47 | K31: 2229 | L31: 0.054733064 | M31: 122 | O31: 77 | P31: 2 | Q31: 47
A32: • | B32: KD Thuê máy | D32: 399 | E32: 0.72180451 | F32: 288 | H32: 182 | J32: 106 | K32: 399 | L32: 0.72180451 | M32: 288 | O32: 182 | Q32: 106
A33: 5.2 | B33: Xesco - KT | D33: 3379 | E33: 0.55548979 | F33: 1877 | H33: 1272 | I33: 11 | J33: 616 | K33: 3379 | L33: 0.55548979 | M33: 1877 | O33: 1272 | P33: 11 | Q33: 616
A34: • | B34: Thuê máy | D34: 1714 | E34: 0.69953326 | F34: 1199 | H34: 870 | I34: 9 | J34: 338 | K34: 1714 | L34: 0.69953326 | M34: 1199 | O34: 870 | P34: 9 | Q34: 338
A35: • | B35: Metercharge | D35: 280 | E35: 0.59642857 | F35: 167 | J35: 167 | K35: 280 | L35: 0.59642857 | M35: 167 | Q35: 167
A36: • | B36: Dịch vụ | D36: 1385 | E36: 0.36895307 | F36: 511 | H36: 402 | I36: 2 | J36: 111 | K36: 1385 | L36: 0.36895307 | M36: 511 | O36: 402 | P36: 2 | Q36: 111
A37: II | B37: VPS MIỀN TRUNG | C37: 3000 | D37: 2427 | E37: 0.18829831 | F37: 457 | G37: 0 | H37: 230 | I37: 0 | J37: 227 | K37: 2427 | L37: 0.18829831 | M37: 457 | N37: 0 | O37: 230 | P37: 0 | Q37: 227
A38: • | B38: Kinh doanh máy - bán buôn | D38: 1620 | E38: 0.10617284 | F38: 172 | L38: 0.11 | M38: 172
A39: • | B39: Kinh doanh linh kiện - bán buôn | D39: 306 | E39: 0.16013072 | F39: 49 | L39: 0.16 | M39: 49
A40: • | B40: Shopee-Online | D40: 106 | E40: 0.08490566 | F40: 9 | L40: 0.08 | M40: 9
...

Sheet Thang_02
A1: MÁY VĂN PHÒNG HÀNG ĐẦU VIỆT NAM - TẬP ĐOÀN VPS
A2: BÁO CÁO KẾT QUẢ KINH DOANH HỢP NHẤT (P&L)
A3: TỔNG HỢP DOANH SỐ, LỢI NHUẬN TRƯỚC THUẾ • KỲ BÁO CÁO: THÁNG 02/2026 VÀ LŨY KẾ 2 THÁNG 2026
Q4: Đơn vị tính: Triệu đồng
A5: TT | B5: NỘI DUNG | C5: VỐN ĐT | D5: THÁNG 02 | K5: LŨY KẾ 2 THÁNG 2026
D6: DS | E6: % LG | F6: LG | G6: HT LG | H6: CHI PHÍ | I6: TN KHÁC | J6: LNTT | K6: DS | L6: % LG | M6: LG | N6: HT LG | O6: CHI PHÍ | P6: TN KHÁC | Q6: LNTT
A7: I | B7: MIỀN BẮC | C7: 90000 | D7: 8344 | E7: 0.21045062 | F7: 1756 | G7: 79 | H7: 3703 | I7: 1061 | J7: -2123 | K7: 35784 | L7: 0.27266376 | M7: 9757 | N7: 1152 | O7: 11927 | P7: 2169 | Q7: 1151
A8: 1 | B8: THH (Tân Hồng Hà) | C8: 50000 | D8: 4434 | E8: 0.15042851 | F8: 667 | G8: 0 | H8: 1791 | I8: 0 | J8: -1124 | K8: 26058 | L8: 0.2806048 | M8: 7312 | N8: 0 | O8: 5672 | P8: 1 | Q8: 1642
A9: a | B9: Khối dịch vụ kỹ thuật | D9: 1473 | E9: 0.2892057 | F9: 426 | H9: 753 | J9: -327 | K9: 3697 | L9: 0.32837436 | M9: 1214 | O9: 1524 | P9: 1 | Q9: -309
A10: a.1 | B10: Tổ Dịch vụ | E10: 0.32 | L10: 0.31
A11: a.2 | B11: Tổ mực in | E11: 0.61 | L11: 0.5
A12: a.3 | B12: Thuê máy | E12: 0.16 | L12: 0.27
A13: a.4 | B13: Metercharge | E13: 0.36 | L13: 0.5
A14: a.5 | B14: Kinh doanh Online | E14: 0.03 | L14: 0.05 | M14: 12400
A15: b | B15: Kinh doanh tổng hợp | E15: 0.04 | H15: 166 | J15: -112 | L15: 0.07 | O15: 305 | Q15: -94
A16: c | B16: Kinh doanh bán buôn | E16: 0.11 | H16: 369 | J16: -181 | L16: 0.08 | O16: 820 | P16: 1 | Q16: -257
A17: d | B17: Dự án | H17: 503 | J17: -503 | L17: 0.42 | O17: 3023 | Q17: 2302
A18: 2 | B18: Việt | C18: 10000 | D18: 3246 | E18: 0.28804683 | F18: 935 | G18: 1 | H18: 967 | I18: 0 | J18: -31 | K18: 8639 | L18: 0.251881 | M18: 2176 | N18: 34 | O18: 2010 | P18: 5 | Q18: 205
A19: 2.1 | B19: Thuê máy | D19: 1334 | E19: 0.56971514 | F19: 760 | H19: 644 | J19: 116 | K19: 2911 | L19: 0.56578495 | M19: 1647 | O19: 1331 | Q19: 322
A20: 2.2 | B20: KDTH | E20: 0.1 | F20: 93 | H20: 139 | J20: -46 | K20: 2849 | L20: 0.094770095 | M20: 270 | O20: 299 | Q20: -29
A21: 2.3 | B21: KD online | E21: 0.08 | F21: 70 | H21: 151 | J21: -81 | K21: 2714 | L21: 0.070007369 | M21: 190 | O21: 316 | Q21: -126
A22: 2.4 | B22: Cửa hàng | E22: 0.74 | F22: 12 | H22: 33 | J22: -21 | K22: 165 | L22: 0.41818182 | M22: 69 | O22: 65 | Q22: 4
A23: 3 | B23: ITSS | C23: 5000 | D23: 232 | E23: 0.32327586 | F23: 75 | H23: 116 | J23: -41 | K23: 655 | L23: 0.29007634 | M23: 190 | O23: 240 | Q23: -50
A24: 4 | B24: CTY VPS | C24: 10000 | D24: 432 | E24: 0.18287037 | F24: 79 | G24: 78 | H24: 829 | I24: 1061 | J24: -928 | K24: 432 | L24: 0 | M24: 0 | N24: 1118 | O24: 4006 | P24: 2163 | Q24: -646
A25: 4.1 | B25: VP VPS - hoạt động KD | D25: 432 | E25: 0.18287037 | F25: 79 | G25: 78 | H25: 829 | I25: 383 | J25: -289 | K25: 432 | L25: 0.18287037 | M25: 79 | N25: 1118 | O25: 1382 | P25: 633 | Q25: 448
A26: 4.2 | B26: HĐ đầu tư Tài chính | H26: 1317 | I26: 678 | J26: -639 | O26: 2624 | P26: 1530 | Q26: -1094
A27: 5 | B27: XESCO (Xem Sơn) | C27: 15000 | D27: 6330 | E27: 0.34375987 | F27: 2176 | G27: 0 | H27: 2033 | I27: -8 | J27: 135 | K27: 16410 | L27: 0.30767824 | M27: 5049 | N27: 0 | O27: 4159 | P27: 10 | Q27: 900
A28: 5.1 | B28: Xesco - KD | D28: 3856 | E28: 0.18620332 | F28: 718 | H28: 760 | I28: -5 | J28: -47 | K28: 10557 | L28: 0.16235673 | M28: 1714 | O28: 1614 | P28: 3 | Q28: 103
A29: • | B29: Bán máy lẻ | D29: 327 | E29: 0.24159021 | F29: 79 | H29: 109 | J29: -30 | K29: 992 | L29: 0.28024194 | M29: 278 | O29: 244 | P29: 1 | Q29: 35
A30: • | B30: KD sỉ | D30: 2004 | E30: 0.19810379 | F30: 397 | H30: 440 | I30: -3 | J30: -46 | K30: 5412 | L30: 0.14486327 | M30: 784 | O30: 900 | P30: 1 | Q30: -115
A31: • | B31: KD Online | D31: 1198 | E31: 0.021702838 | F31: 26 | H31: 85 | I31: -2 | J31: -61 | K31: 3427 | L31: 0.04289466 | M31: 147 | O31: 162 | P31: 1 | Q31: -14
A32: • | B32: KD Thuê máy | D32: 327 | E32: 0.66055046 | F32: 216 | H32: 126 | J32: 90 | K32: 725 | L32: 0.69517241 | M32: 504 | O32: 308 | Q32: 196
A33: 5.2 | B33: Xesco - KT | D33: 2474 | E33: 0.58932902 | F33: 1458 | H33: 1273 | I33: -4 | J33: 181 | K33: 5853 | L33: 0.56979327 | M33: 3335 | O33: 2545 | P33: 7 | Q33: 797
A34: • | B34: Thuê máy | D34: 1434 | E34: 0.70990237 | F34: 1018 | H34: 851 | I34: -2 | J34: 165 | K34: 3148 | L34: 0.70425667 | M34: 2217 | O34: 1721 | P34: 7 | Q34: 503
A35: • | B35: Metercharge | D35: 241 | E35: 0.69709544 | F35: 168 | J35: 168 | K35: 521 | L35: 0.64299424 | M35: 335 | Q35: 335
A36: • | B36: Dịch vụ | D36: 799 | E36: 0.34042553 | F36: 272 | H36: 422 | I36: -2 | J36: -152 | K36: 2184 | L36: 0.35851648 | M36: 783 | O36: 824 | Q36: -41
A37: II | B37: VPS MIỀN TRUNG | C37: 3000 | D37: 1030 | E37: 0.25339806 | F37: 261 | G37: 0 | H37: 201 | I37: 0 | J37: 60 | K37: 3457 | L37: 0.20740526 | M37: 717 | N37: 0 | O37: 431 | P37: 0 | Q37: 286
A38: • | B38: Kinh doanh máy - bán buôn | D38: 498 | E38: 0.10240964 | F38: 51 | L38: 0.11 | M38: 222
A39: • | B39: Kinh doanh linh kiện - bán buôn | D39: 193 | E39: 0.16062176 | F39: 31 | L39: 0.16 | M39: 80
A40: • | B40: Shopee-Online | D40: 28 | E40: 0.071428571 | F40: 2 | L40: 0.08 | M40: 11
...

Sheet Thang_03
A1: MÁY VĂN PHÒNG HÀNG ĐẦU VIỆT NAM - TẬP ĐOÀN VPS
A2: BÁO CÁO KẾT QUẢ KINH DOANH HỢP NHẤT (P&L)
A3: TỔNG HỢP DOANH SỐ, LỢI NHUẬN TRƯỚC THUẾ • KỲ BÁO CÁO: THÁNG 03/2026 VÀ LŨY KẾ 3 THÁNG 2026
Q4: Đơn vị tính: Triệu đồng
A5: TT | B5: NỘI DUNG | C5: VỐN ĐT | D5: THÁNG 03 | K5: LŨY KẾ 3 THÁNG 2026
D6: DS | E6: % LG | F6: LG | G6: HT LG | H6: CHI PHÍ | I6: TN KHÁC | J6: LNTT | K6: DS | L6: % LG | M6: LG | N6: HT LG | O6: CHI PHÍ | P6: TN KHÁC | Q6: LNTT
A7: I | B7: MIỀN BẮC | C7: 90000 | D7: 15688 | E7: 0.18447221 | F7: 2894 | G7: 317 | H7: 3253 | I7: 1118 | J7: 1 | K7: 51470 | L7: 0.24577424 | M7: 12650 | N7: 1468 | O7: 16324 | P7: 3289 | Q7: 1084
A8: 1 | B8: THH (Tân Hồng Hà) | C8: 50000 | D8: 8494 | E8: 0.20626324 | F8: 1752 | G8: 0 | H8: 1372 | I8: 5 | J8: 386 | K8: 34551 | L8: 0.26236578 | M8: 9065 | N8: 0 | O8: 7043 | P8: 6 | Q8: 2028
A9: a | B9: Khối dịch vụ kỹ thuật | D9: 2649 | E9: 0.39146848 | F9: 1037 | H9: 802 | I9: -1 | J9: 234 | K9: 6346 | L9: 0.35471163 | M9: 2251 | O9: 2326 | Q9: -75
A10: a.1 | B10: Tổ Dịch vụ | E10: 0.38 | L10: 0.34
A11: a.2 | B11: Tổ mực in | E11: 0.49 | L11: 0.5
A12: a.3 | B12: Thuê máy | E12: 0.28 | L12: 0.28
A13: a.4 | B13: Metercharge | E13: 0.61 | L13: 0.55
A14: a.5 | B14: Kinh doanh Online | L14: 0.04 | M14: 12900
A15: b | B15: Kinh doanh tổng hợp | E15: 0.09 | H15: 173 | I15: 3 | J15: 23 | L15: 0.08 | O15: 478 | P15: 3 | Q15: -71
A16: c | B16: Kinh doanh bán buôn | E16: 0.14 | H16: 335 | I16: 3 | J16: 190 | L16: 0.1 | O16: 1155 | P16: 4 | Q16: -67
A17: d | B17: Dự án | H17: 62 | J17: -62 | L17: 0.42 | O17: 3084 | Q17: 2241
A18: 2 | B18: Việt | C18: 10000 | D18: 6144 | E18: 0.17903646 | F18: 1100 | G18: 2 | H18: 934 | I18: 0 | J18: 170 | K18: 14781 | L18: 0.22156823 | M18: 3275 | N18: 36 | O18: 2944 | P18: 7 | Q18: 374
A19: 2.1 | B19: Thuê máy | D19: 1451 | E19: 0.56099242 | F19: 814 | H19: 605 | I19: 1 | J19: 210 | K19: 4362 | L19: 0.56419074 | M19: 2461 | O19: 1936 | Q19: 531
A20: 2.2 | B20: KDTH | E20: 0.06 | F20: 118 | H20: 138 | I20: 1 | J20: -19 | K20: 4708 | L20: 0.082412914 | M20: 388 | O20: 437 | Q20: -48
A21: 2.3 | B21: KD online | E21: 0.05 | F21: 139 | H21: 160 | J21: -21 | K21: 5459 | L21: 0.060084265 | M21: 328 | O21: 476 | Q21: -148
A22: 2.4 | B22: Cửa hàng | E22: 0.34 | F22: 29 | H22: 31 | J22: -2 | K22: 252 | L22: 0.38888889 | M22: 98 | O22: 96 | Q22: 2
A23: 3 | B23: ITSS | C23: 5000 | D23: 179 | E23: 0.24022346 | F23: 43 | H23: 118 | J23: -75 | K23: 834 | L23: 0.2793765 | M23: 233 | O23: 358 | Q23: -125
A24: 4 | B24: CTY VPS | C24: 10000 | D24: 872 | E24: -0.001146789 | F24: -1 | G24: 315 | H24: 829 | I24: 1113 | J24: -480 | K24: 1304 | L24: 0 | M24: 0 | N24: 0 | O24: 5979 | P24: 3276 | Q24: -1193
A25: 4.1 | B25: VP VPS - hoạt động KD | D25: 872 | E25: -0.001146789 | F25: -1 | G25: 315 | H25: 658 | I25: 422 | J25: 78 | K25: 1304 | L25: 0.059815951 | M25: 78 | N25: 1432 | O25: 2045 | P25: 1055 | Q25: 520
A26: 4.2 | B26: HĐ đầu tư Tài chính | H26: 1249 | I26: 691 | J26: -558 | O26: 3934 | P26: 2221 | Q26: -1713
A27: 5 | B27: XESCO (Xem Sơn) | C27: 15000 | D27: 11914 | E27: 0.2118516 | F27: 2524 | G27: 0 | H27: 2097 | I27: -7 | J27: 420 | K27: 28324 | L27: 0.26740573 | M27: 7574 | N27: 0 | O27: 6256 | P27: 2 | Q27: 1320
A28: 5.1 | B28: Xesco - KD | D28: 8926 | E28: 0.11550527 | F28: 1031 | H28: 760 | I28: -6 | J28: 265 | K28: 19483 | L28: 0.14084073 | M28: 2744 | O28: 2374 | P28: -4 | Q28: 366
A29: • | B29: Bán máy lẻ | D29: 347 | E29: 0.30259366 | F29: 105 | H29: 71 | I29: 1 | J29: 35 | K29: 1339 | L29: 0.28678118 | M29: 384 | O29: 315 | P29: 1 | Q29: 70
A30: • | B30: KD sỉ | D30: 4169 | E30: 0.10913888 | F30: 455 | H30: 434 | I30: -4 | J30: 17 | K30: 9581 | L30: 0.12931844 | M30: 1239 | O30: 1334 | P30: -3 | Q30: -98
A31: • | B31: KD Online | D31: 3997 | E31: 0.041280961 | F31: 165 | H31: 109 | I31: -3 | J31: 53 | K31: 7424 | L31: 0.042025862 | M31: 312 | O31: 271 | P31: -2 | Q31: 39
A32: • | B32: KD Thuê máy | D32: 413 | E32: 0.7409201 | F32: 306 | H32: 146 | J32: 160 | K32: 1139 | L32: 0.71115013 | M32: 810 | O32: 454 | Q32: 356
A33: 5.2 | B33: Xesco - KT | D33: 2988 | E33: 0.5 | F33: 1494 | H33: 1337 | I33: -2 | J33: 155 | K33: 8841 | L33: 0.54620518 | M33: 4829 | O33: 3882 | P33: 4 | Q33: 951
A34: • | B34: Thuê máy | D34: 1392 | E34: 0.6091954 | F34: 848 | H34: 820 | I34: -1 | J34: 27 | K34: 4540 | L34: 0.67511013 | M34: 3065 | O34: 2541 | P34: 5 | Q34: 529
A35: • | B35: Metercharge | D35: 268 | E35: 0.54477612 | F35: 146 | J35: 146 | K35: 789 | L35: 0.60963245 | M35: 481 | Q35: 481
A36: • | B36: Dịch vụ | D36: 1327 | E36: 0.37678975 | F36: 500 | H36: 517 | I36: -1 | J36: -18 | K36: 3511 | L36: 0.36542296 | M36: 1283 | O36: 1341 | P36: -1 | Q36: -59
A37: II | B37: VPS MIỀN TRUNG | C37: 3000 | D37: 1981 | E37: 0.17970722 | F37: 356 | G37: 0 | H37: 202 | I37: 0 | J37: 154 | K37: 5438 | L37: 0.19731519 | M37: 1073 | N37: 0 | O37: 633 | P37: 0 | Q37: 440
A38: • | B38: Kinh doanh máy - bán buôn | D38: 1107 | E38: 0.067750678 | F38: 75 | K38: 3225 | L38: 0.092403101 | M38: 298
A39: • | B39: Kinh doanh linh kiện - bán buôn | D39: 329 | E39: 0.18541033 | F39: 61 | K39: 828 | L39: 0.17028986 | M39: 141
A40: • | B40: Shopee-Online | D40: 116 | E40: 0.068965517 | F40: 8 | K40: 251 | L40: 0.075697211 | M40: 19
...

Sheet Thang_04
A1: MÁY VĂN PHÒNG HÀNG ĐẦU VIỆT NAM - TẬP ĐOÀN VPS
A2: BÁO CÁO KẾT QUẢ KINH DOANH HỢP NHẤT (P&L)
A3: TỔNG HỢP DOANH SỐ, LỢI NHUẬN TRƯỚC THUẾ • KỲ BÁO CÁO: THÁNG 04/2026 VÀ LŨY KẾ 4 THÁNG 2026
Q4: Đơn vị tính: Triệu đồng
A5: TT | B5: NỘI DUNG | C5: VỐN ĐT | D5: THÁNG 04 | K5: LŨY KẾ 4 THÁNG 2026
D6: DS | E6: % LG | F6: LG | G6: HT LG | H6: CHI PHÍ | I6: TN KHÁC | J6: LNTT | K6: DS | L6: % LG | M6: LG | N6: HT LG | O6: CHI PHÍ | P6: TN KHÁC | Q6: LNTT
A7: I | B7: MIỀN BẮC | C7: 90000 | D7: 14820 | E7: 0.19750337 | F7: 2927 | G7: 2 | H7: 3293 | I7: 1114 | J7: -611 | K7: 66289 | L7: 0.2349862 | M7: 15577 | N7: 1470 | O7: 20981 | P7: 4629 | Q7: 695
A8: 1 | B8: THH (Tân Hồng Hà) | C8: 50000 | D8: 8436 | E8: 0.17342342 | F8: 1463 | G8: 0 | H8: 1390 | I8: 1 | J8: 74 | K8: 42987 | L8: 0.24491125 | M8: 10528 | N8: 0 | O8: 8433 | P8: 7 | Q8: 2102
A9: a | B9: Khối dịch vụ kỹ thuật | D9: 2455 | E9: 0.37352342 | F9: 917 | H9: 819 | I9: 1 | J9: 99 | K9: 8801 | L9: 0.3599591 | M9: 3168 | O9: 3145 | Q9: 23
A10: a.1 | B10: Tổ Dịch vụ | E10: 0.36 | L10: 0.35
A11: a.2 | B11: Tổ mực in | E11: 0.5 | L11: 0.5
A12: a.3 | B12: Thuê máy | E12: 0.34 | L12: 0.29
A13: a.4 | B13: Metercharge | E13: 0.4 | L13: 0.51
A14: a.5 | B14: Kinh doanh Online | L14: 0.03
A15: b | B15: Kinh doanh tổng hợp | E15: 0.07 | H15: 172 | J15: 2 | L15: 0.08 | O15: 650 | P15: 3 | Q15: -69
A16: c | B16: Kinh doanh bán buôn | E16: 0.11 | H16: 338 | J16: 35 | L16: 0.11 | O16: 1492 | P16: 3 | Q16: -32
A17: d | B17: Dự án | H17: 62 | J17: -62 | L17: 0.42 | O17: 3147 | Q17: 2179
A18: 2 | B18: Việt | C18: 10000 | D18: 5816 | E18: 0.23297799 | F18: 1355 | G18: 2 | H18: 960 | I18: 0 | J18: 401 | K18: 20597 | L18: 0.22474147 | M18: 4629 | N18: 38 | O18: 3905 | P18: 13 | Q18: 776
A19: 2.1 | B19: Thuê máy | D19: 1770 | E19: 0.57288136 | F19: 1014 | H19: 629 | I19: 4 | J19: 388 | K19: 6132 | L19: 0.56669928 | M19: 3475 | O19: 2565 | Q19: 920
A20: 2.2 | B20: KDTH | E20: 0.09 | F20: 117 | H20: 141 | J20: -24 | K20: 6045 | L20: 0.083540116 | M20: 505 | O20: 577 | Q20: -71
A21: 2.3 | B21: KD online | E21: 0.06 | F21: 159 | H21: 158 | J21: 1 | K21: 8052 | L21: 0.060481868 | M21: 487 | O21: 634 | Q21: -147
A22: 2.4 | B22: Cửa hàng | E22: 0.56 | F22: 65 | H22: 32 | J22: 33 | K22: 369 | L22: 0.44173442 | M22: 163 | O22: 128 | Q22: 35
A23: 3 | B23: ITSS | C23: 5000 | D23: 257 | E23: 0.33463035 | F23: 86 | H23: 114 | J23: -28 | K23: 1090 | L23: 0.29266055 | M23: 319 | O23: 472 | Q23: -153
A24: 4 | B24: CTY VPS | C24: 10000 | D24: 312 | E24: 0.073717949 | F24: 23 | G24: 0 | H24: 829 | I24: 1113 | J24: -1057 | K24: 1615 | L24: 0 | M24: 0 | N24: 1432 | O24: 8171 | P24: 4609 | Q24: -2029
A25: 4.1 | B25: VP VPS - hoạt động KD | D25: 312 | E25: 0.073717949 | F25: 23 | H25: 607 | I25: 422 | J25: -162 | K25: 1615 | L25: 0.0625387 | M25: 101 | N25: 1432 | O25: 2651 | P25: 1697 | Q25: 579
A26: 4.2 | B26: HĐ đầu tư Tài chính | H26: 1586 | I26: 691 | J26: -895 | O26: 5520 | P26: 2912 | Q26: -2608
A27: 5 | B27: XESCO (Xem Sơn) | C27: 15000 | D27: 10140 | E27: 0.26656805 | F27: 2703 | G27: 0 | H27: 2036 | I27: -14 | J27: 653 | K27: 38464 | L27: 0.2671849 | M27: 10277 | N27: 0 | O27: 8292 | P27: -12 | Q27: 1973
A28: 5.1 | B28: Xesco - KD | D28: 7296 | E28: 0.14432566 | F28: 1053 | H28: 735 | I28: -10 | J28: 308 | K28: 26780 | L28: 0.14182226 | M28: 3798 | O28: 3109 | P28: -8 | Q28: 681
A29: • | B29: Bán máy lẻ | D29: 270 | E29: 0.21481481 | F29: 58 | H29: 58 | K29: 1609 | L29: 0.27470479 | M29: 442 | O29: 373 | P29: -1 | Q29: 68
A30: • | B30: KD sỉ | D30: 3530 | E30: 0.18328612 | F30: 647 | H30: 428 | I30: -5 | J30: 214 | K30: 13112 | L30: 0.14376144 | M30: 1885 | O30: 1762 | Q30: 123
A31: • | B31: KD Online | D31: 3116 | E31: 0.025353017 | F31: 79 | H31: 107 | I31: -4 | J31: -32 | K31: 10540 | L31: 0.037191651 | M31: 392 | O31: 378 | P31: -6 | Q31: 8
A32: • | B32: KD Thuê máy | D32: 380 | E32: 0.70789474 | F32: 269 | H32: 142 | I32: -1 | J32: 126 | K32: 1519 | L32: 0.71033575 | M32: 1079 | O32: 596 | P32: -1 | Q32: 482
A33: 5.2 | B33: Xesco - KT | D33: 2844 | E33: 0.58016878 | F33: 1650 | H33: 1301 | I33: -4 | J33: 345 | K33: 11684 | L33: 0.554519 | M33: 6479 | O33: 5183 | P33: -6 | Q33: 1290
A34: • | B34: Thuê máy | D34: 1451 | E34: 0.70572019 | F34: 1024 | H34: 801 | I34: -2 | J34: 221 | K34: 5991 | L34: 0.68252379 | M34: 4089 | O34: 3342 | P34: -4 | Q34: 743
A35: • | B35: Metercharge | D35: 270 | E35: 0.74074074 | F35: 200 | J35: 200 | K35: 1059 | L35: 0.64305949 | M35: 681 | Q35: 681
A36: • | B36: Dịch vụ | D36: 1123 | E36: 0.37934105 | F36: 426 | H36: 500 | I36: -2 | J36: -76 | K36: 4634 | L36: 0.36879586 | M36: 1709 | O36: 1841 | P36: -2 | Q36: -134
A37: II | B37: VPS MIỀN TRUNG | C37: 3000 | D37: 1477 | E37: 0.22477996 | F37: 332 | G37: 0 | H37: 213 | I37: 0 | J37: 120 | K37: 6916 | L37: 0.2032967 | M37: 1406 | N37: 0 | O37: 846 | P37: 0 | Q37: 560
A38: • | B38: Kinh doanh máy - bán buôn | D38: 446 | E38: 0.071748879 | F38: 32 | K38: 3671 | L38: 0.089893762 | M38: 330
A39: • | B39: Kinh doanh linh kiện - bán buôn | D39: 280 | E39: 0.175 | F39: 49 | K39: 1108 | L39: 0.17148014 | M39: 190
A40: • | B40: Shopee-Online | D40: 293 | E40: 0.058020478 | F40: 17 | K40: 544 | L40: 0.068014706 | M40: 37
...

Sheet Thang_05
A1: MÁY VĂN PHÒNG HÀNG ĐẦU VIỆT NAM - TẬP ĐOÀN VPS
A2: BÁO CÁO KẾT QUẢ KINH DOANH HỢP NHẤT (P&L)
A3: TỔNG HỢP DOANH SỐ, LỢI NHUẬN TRƯỚC THUẾ • KỲ BÁO CÁO: THÁNG 05/2026 VÀ LŨY KẾ 5 THÁNG 2026
Q4: Đơn vị tính: Triệu đồng
A5: TT | B5: NỘI DUNG | C5: VỐN ĐT | D5: THÁNG 05 | K5: LŨY KẾ 5 THÁNG 2026
D6: DS | E6: % LG | F6: LG | G6: HT LG | H6: CHI PHÍ | I6: TN KHÁC | J6: LNTT | K6: DS | L6: % LG | M6: LG | N6: HT LG | O6: CHI PHÍ | P6: TN KHÁC | Q6: LNTT
A7: I | B7: MIỀN BẮC | C7: 90000 | D7: =D8+D18+D23+D24+D27 | E7: =IF(D7>0, F7/D7, 0) | F7: =F8+F18+F23+F24+F27 | G7: =G8+G18+G23+G24+G27 | H7: =H8+H18+H23+H24+H27 | I7: =I8+I18+I23+I24+I27 | J7: =J8+J18+J23+J24+J27 | K7: =K8+K18+K23+K24+K27 | L7: =IF(K7>0, M7/K7, 0) | M7: =M8+M18+M23+M24+M27 | N7: =N8+N18+N23+N24+N27 | O7: =O8+O18+O23+O24+O27 | P7: =P8+P18+P23+P24+P27 | Q7: ='Thang_04'!Q7+J7
A8: 1 | B8: THH (Tân Hồng Hà) | C8: 50000 | D8: =D9+D15+D16+D17 | E8: =IF(D8>0, F8/D8, 0) | F8: =F9+F15+F16+F17 | G8: =G9+G15+G16+G17 | H8: =H9+H15+H16+H17 | I8: =I9+I15+I16+I17 | J8: =J9+J15+J16+J17 | K8: =K9+K15+K16+K17 | L8: =IF(K8>0, M8/K8, 0) | M8: =M9+M15+M16+M17 | N8: =N9+N15+N16+N17 | O8: =O9+O15+O16+O17 | P8: =P9+P15+P16+P17 | Q8: ='Thang_04'!Q8+J8
A9: a | B9: Khối dịch vụ kỹ thuật | D9: =SUM(D10:D14) | E9: =IF(D9>0, F9/D9, 0) | F9: =SUM(F10:F14) | G9: =SUM(G10:G14) | H9: =SUM(H10:H14) | I9: =SUM(I10:I14) | J9: =F9+G9-H9+I9 | K9: =SUM(K10:K14) | L9: =IF(K9>0, M9/K9, 0) | M9: =SUM(M10:M14) | N9: =SUM(N10:N14) | O9: =SUM(O10:O14) | P9: =SUM(P10:P14) | Q9: ='Thang_04'!Q9+J9
A10: a.1 | B10: Tổ Dịch vụ | E10: =IF(D10>0, F10/D10, 0) | J10: =F10+G10-H10+I10 | K10: ='Thang_04'!K10+D10 | L10: =IF(K10>0, M10/K10, 0) | M10: ='Thang_04'!M10+F10 | N10: ='Thang_04'!N10+G10 | O10: ='Thang_04'!O10+H10 | P10: ='Thang_04'!P10+I10 | Q10: ='Thang_04'!Q10+J10
A11: a.2 | B11: Tổ mực in | E11: =IF(D11>0, F11/D11, 0) | J11: =F11+G11-H11+I11 | K11: ='Thang_04'!K11+D11 | L11: =IF(K11>0, M11/K11, 0) | M11: ='Thang_04'!M11+F11 | N11: ='Thang_04'!N11+G11 | O11: ='Thang_04'!O11+H11 | P11: ='Thang_04'!P11+I11 | Q11: ='Thang_04'!Q11+J11
A12: a.3 | B12: Thuê máy | E12: =IF(D12>0, F12/D12, 0) | J12: =F12+G12-H12+I12 | K12: ='Thang_04'!K12+D12 | L12: =IF(K12>0, M12/K12, 0) | M12: ='Thang_04'!M12+F12 | N12: ='Thang_04'!N12+G12 | O12: ='Thang_04'!O12+H12 | P12: ='Thang_04'!P12+I12 | Q12: ='Thang_04'!Q12+J12
A13: a.4 | B13: Metercharge | E13: =IF(D13>0, F13/D13, 0) | J13: =F13+G13-H13+I13 | K13: ='Thang_04'!K13+D13 | L13: =IF(K13>0, M13/K13, 0) | M13: ='Thang_04'!M13+F13 | N13: ='Thang_04'!N13+G13 | O13: ='Thang_04'!O13+H13 | P13: ='Thang_04'!P13+I13 | Q13: ='Thang_04'!Q13+J13
A14: a.5 | B14: Kinh doanh Online | E14: =IF(D14>0, F14/D14, 0) | J14: =F14+G14-H14+I14 | K14: ='Thang_04'!K14+D14 | L14: =IF(K14>0, M14/K14, 0) | M14: ='Thang_04'!M14+F14 | N14: ='Thang_04'!N14+G14 | O14: ='Thang_04'!O14+H14 | P14: ='Thang_04'!P14+I14 | Q14: ='Thang_04'!Q14+J14
A15: b | B15: Kinh doanh tổng hợp | E15: =IF(D15>0, F15/D15, 0) | J15: =F15+G15-H15+I15 | K15: ='Thang_04'!K15+D15 | L15: =IF(K15>0, M15/K15, 0) | M15: ='Thang_04'!M15+F15 | N15: ='Thang_04'!N15+G15 | O15: ='Thang_04'!O15+H15 | P15: ='Thang_04'!P15+I15 | Q15: ='Thang_04'!Q15+J15
A16: c | B16: Kinh doanh bán buôn | E16: =IF(D16>0, F16/D16, 0) | J16: =F16+G16-H16+I16 | K16: ='Thang_04'!K16+D16 | L16: =IF(K16>0, M16/K16, 0) | M16: ='Thang_04'!M16+F16 | N16: ='Thang_04'!N16+G16 | O16: ='Thang_04'!O16+H16 | P16: ='Thang_04'!P16+I16 | Q16: ='Thang_04'!Q16+J16
A17: d | B17: Dự án | E17: =IF(D17>0, F17/D17, 0) | J17: =F17+G17-H17+I17 | K17: ='Thang_04'!K17+D17 | L17: =IF(K17>0, M17/K17, 0) | M17: ='Thang_04'!M17+F17 | N17: ='Thang_04'!N17+G17 | O17: ='Thang_04'!O17+H17 | P17: ='Thang_04'!P17+I17 | Q17: ='Thang_04'!Q17+J17
A18: 2 | B18: Việt | C18: 10000 | D18: =SUM(D19:D22) | E18: =IF(D18>0, F18/D18, 0) | F18: =SUM(F19:F22) | G18: =SUM(G19:G22) | H18: =SUM(H19:H22) | I18: =SUM(I19:I22) | J18: =SUM(J19:J22) | K18: =SUM(K19:K22) | L18: =IF(K18>0, M18/K18, 0) | M18: =SUM(M19:M22) | N18: =SUM(N19:N22) | O18: =SUM(O19:O22) | P18: =SUM(P19:P22) | Q18: ='Thang_04'!Q18+J18
A19: 2.1 | B19: Thuê máy | E19: =IF(D19>0, F19/D19, 0) | J19: =F19+G19-H19+I19 | K19: ='Thang_04'!K19+D19 | L19: =IF(K19>0, M19/K19, 0) | M19: ='Thang_04'!M19+F19 | N19: ='Thang_04'!N19+G19 | O19: ='Thang_04'!O19+H19 | P19: ='Thang_04'!P19+I19 | Q19: ='Thang_04'!Q19+J19
A20: 2.2 | B20: KDTH | E20: =IF(D20>0, F20/D20, 0) | J20: =F20+G20-H20+I20 | K20: ='Thang_04'!K20+D20 | L20: =IF(K20>0, M20/K20, 0) | M20: ='Thang_04'!M20+F20 | N20: ='Thang_04'!N20+G20 | O20: ='Thang_04'!O20+H20 | P20: ='Thang_04'!P20+I20 | Q20: ='Thang_04'!Q20+J20
A21: 2.3 | B21: KD online | E21: =IF(D21>0, F21/D21, 0) | J21: =F21+G21-H21+I21 | K21: ='Thang_04'!K21+D21 | L21: =IF(K21>0, M21/K21, 0) | M21: ='Thang_04'!M21+F21 | N21: ='Thang_04'!N21+G21 | O21: ='Thang_04'!O21+H21 | P21: ='Thang_04'!P21+I21 | Q21: ='Thang_04'!Q21+J21
A22: 2.4 | B22: Cửa hàng | E22: =IF(D22>0, F22/D22, 0) | J22: =F22+G22-H22+I22 | K22: ='Thang_04'!K22+D22 | L22: =IF(K22>0, M22/K22, 0) | M22: ='Thang_04'!M22+F22 | N22: ='Thang_04'!N22+G22 | O22: ='Thang_04'!O22+H22 | P22: ='Thang_04'!P22+I22 | Q22: ='Thang_04'!Q22+J22
A23: 3 | B23: ITSS | C23: 5000 | E23: =IF(D23>0, F23/D23, 0) | J23: =F23+G23-H23+I23 | K23: ='Thang_04'!K23+D23 | L23: =IF(K23>0, M23/K23, 0) | M23: ='Thang_04'!M23+F23 | N23: ='Thang_04'!N23+G23 | O23: ='Thang_04'!O23+H23 | P23: ='Thang_04'!P23+I23 | Q23: ='Thang_04'!Q23+J23
A24: 4 | B24: CTY VPS | C24: 10000 | D24: =SUM(D25:D26) | E24: =IF(D24>0, F24/D24, 0) | F24: =SUM(F25:F26) | G24: =SUM(G25:G26) | H24: =SUM(H25:H26) | I24: =SUM(I25:I26) | J24: =SUM(J25:J26) | K24: =SUM(K25:K26) | L24: =IF(K24>0, M24/K24, 0) | M24: =SUM(M25:M26) | N24: =SUM(N25:N26) | O24: =SUM(O25:O26) | P24: =SUM(P25:P26) | Q24: ='Thang_04'!Q24+J24
A25: 4.1 | B25: VP VPS - hoạt động KD | E25: =IF(D25>0, F25/D25, 0) | J25: =F25+G25-H25+I25 | K25: ='Thang_04'!K25+D25 | L25: =IF(K25>0, M25/K25, 0) | M25: ='Thang_04'!M25+F25 | N25: ='Thang_04'!N25+G25 | O25: ='Thang_04'!O25+H25 | P25: ='Thang_04'!P25+I25 | Q25: ='Thang_04'!Q25+J25
A26: 4.2 | B26: HĐ đầu tư Tài chính | E26: =IF(D26>0, F26/D26, 0) | J26: =F26+G26-H26+I26 | K26: ='Thang_04'!K26+D26 | L26: =IF(K26>0, M26/K26, 0) | M26: ='Thang_04'!M26+F26 | N26: ='Thang_04'!N26+G26 | O26: ='Thang_04'!O26+H26 | P26: ='Thang_04'!P26+I26 | Q26: ='Thang_04'!Q26+J26
A27: 5 | B27: XESCO (Xem Sơn) | C27: 15000 | D27: =D28+D33 | E27: =IF(D27>0, F27/D27, 0) | F27: =F28+F33 | G27: =G28+G33 | H27: =H28+H33 | I27: =I28+I33 | J27: =J28+J33 | K27: =K28+K33 | L27: =IF(K27>0, M27/K27, 0) | M27: =M28+M33 | N27: =N28+N33 | O27: =O28+O33 | P27: =P28+P33 | Q27: ='Thang_04'!Q27+J27
A28: 5.1 | B28: Xesco - KD | D28: =SUM(D29:D32) | E28: =IF(D28>0, F28/D28, 0) | F28: =SUM(F29:F32) | G28: =SUM(G29:G32) | H28: =SUM(H29:H32) | I28: =SUM(I29:I32) | J28: =F28+G28-H28+I28 | K28: =SUM(K29:K32) | L28: =IF(K28>0, M28/K28, 0) | M28: =SUM(M29:M32) | N28: =SUM(N29:N32) | O28: =SUM(O29:O32) | P28: =SUM(P29:P32) | Q28: ='Thang_04'!Q28+J28
A29: • | B29: Bán máy lẻ | E29: =IF(D29>0, F29/D29, 0) | J29: =F29+G29-H29+I29 | K29: ='Thang_04'!K29+D29 | L29: =IF(K29>0, M29/K29, 0) | M29: ='Thang_04'!M29+F29 | N29: ='Thang_04'!N29+G29 | O29: ='Thang_04'!O29+H29 | P29: ='Thang_04'!P29+I29 | Q29: ='Thang_04'!Q29+J29
A30: • | B30: KD sỉ | E30: =IF(D30>0, F30/D30, 0) | J30: =F30+G30-H30+I30 | K30: ='Thang_04'!K30+D30 | L30: =IF(K30>0, M30/K30, 0) | M30: ='Thang_04'!M30+F30 | N30: ='Thang_04'!N30+G30 | O30: ='Thang_04'!O30+H30 | P30: ='Thang_04'!P30+I30 | Q30: ='Thang_04'!Q30+J30
A31: • | B31: KD Online | E31: =IF(D31>0, F31/D31, 0) | J31: =F31+G31-H31+I31 | K31: ='Thang_04'!K31+D31 | L31: =IF(K31>0, M31/K31, 0) | M31: ='Thang_04'!M31+F31 | N31: ='Thang_04'!N31+G31 | O31: ='Thang_04'!O31+H31 | P31: ='Thang_04'!P31+I31 | Q31: ='Thang_04'!Q31+J31
A32: • | B32: KD Thuê máy | E32: =IF(D32>0, F32/D32, 0) | J32: =F32+G32-H32+I32 | K32: ='Thang_04'!K32+D32 | L32: =IF(K32>0, M32/K32, 0) | M32: ='Thang_04'!M32+F32 | N32: ='Thang_04'!N32+G32 | O32: ='Thang_04'!O32+H32 | P32: ='Thang_04'!P32+I32 | Q32: ='Thang_04'!Q32+J32
A33: 5.2 | B33: Xesco - KT | D33: =SUM(D34:D36) | E33: =IF(D33>0, F33/D33, 0) | F33: =SUM(F34:F36) | G33: =SUM(G34:G36) | H33: =SUM(H34:H36) | I33: =SUM(I34:I36) | J33: =F33+G33-H33+I33 | K33: =SUM(K34:K36) | L33: =IF(K33>0, M33/K33, 0) | M33: =SUM(M34:M36) | N33: =SUM(N34:N36) | O33: =SUM(O34:O36) | P33: =SUM(P34:P36) | Q33: ='Thang_04'!Q33+J33
A34: • | B34: Thuê máy | E34: =IF(D34>0, F34/D34, 0) | J34: =F34+G34-H34+I34 | K34: ='Thang_04'!K34+D34 | L34: =IF(K34>0, M34/K34, 0) | M34: ='Thang_04'!M34+F34 | N34: ='Thang_04'!N34+G34 | O34: ='Thang_04'!O34+H34 | P34: ='Thang_04'!P34+I34 | Q34: ='Thang_04'!Q34+J34
A35: • | B35: Metercharge | E35: =IF(D35>0, F35/D35, 0) | J35: =F35+G35-H35+I35 | K35: ='Thang_04'!K35+D35 | L35: =IF(K35>0, M35/K35, 0) | M35: ='Thang_04'!M35+F35 | N35: ='Thang_04'!N35+G35 | O35: ='Thang_04'!O35+H35 | P35: ='Thang_04'!P35+I35 | Q35: ='Thang_04'!Q35+J35
A36: • | B36: Dịch vụ | E36: =IF(D36>0, F36/D36, 0) | J36: =F36+G36-H36+I36 | K36: ='Thang_04'!K36+D36 | L36: =IF(K36>0, M36/K36, 0) | M36: ='Thang_04'!M36+F36 | N36: ='Thang_04'!N36+G36 | O36: ='Thang_04'!O36+H36 | P36: ='Thang_04'!P36+I36 | Q36: ='Thang_04'!Q36+J36
A37: II | B37: VPS MIỀN TRUNG | C37: 3000 | D37: =SUM(D38:D44) | E37: =IF(D37>0, F37/D37, 0) | F37: =SUM(F38:F44) | G37: =SUM(G38:G44) | H37: =SUM(H38:H44) | I37: =SUM(I38:I44) | J37: =SUM(J38:J44) | K37: =SUM(K38:K44) | L37: =IF(K37>0, M37/K37, 0) | M37: =SUM(M38:M44) | N37: =SUM(N38:N44) | O37: =SUM(O38:O44) | P37: =SUM(P38:P44) | Q37: ='Thang_04'!Q37+J37
A38: • | B38: Kinh doanh máy - bán buôn | E38: =IF(D38>0, F38/D38, 0) | J38: =F38+G38-H38+I38 | K38: ='Thang_04'!K38+D38 | L38: =IF(K38>0, M38/K38, 0) | M38: ='Thang_04'!M38+F38 | N38: ='Thang_04'!N38+G38 | O38: ='Thang_04'!O38+H38 | P38: ='Thang_04'!P38+I38 | Q38: ='Thang_04'!Q38+J38
A39: • | B39: Kinh doanh linh kiện - bán buôn | E39: =IF(D39>0, F39/D39, 0) | J39: =F39+G39-H39+I39 | K39: ='Thang_04'!K39+D39 | L39: =IF(K39>0, M39/K39, 0) | M39: ='Thang_04'!M39+F39 | N39: ='Thang_04'!N39+G39 | O39: ='Thang_04'!O39+H39 | P39: ='Thang_04'!P39+I39 | Q39: ='Thang_04'!Q39+J39
A40: • | B40: Shopee-Online | E40: =IF(D40>0, F40/D40, 0) | J40: =F40+G40-H40+I40 | K40: ='Thang_04'!K40+D40 | L40: =IF(K40>0, M40/K40, 0) | M40: ='Thang_04'!M40+F40 | N40: ='Thang_04'!N40+G40 | O40: ='Thang_04'!O40+H40 | P40: ='Thang_04'!P40+I40 | Q40: ='Thang_04'!Q40+J40
...

Sheet Thang_06
A1: MÁY VĂN PHÒNG HÀNG ĐẦU VIỆT NAM - TẬP ĐOÀN VPS
A2: BÁO CÁO KẾT QUẢ KINH DOANH HỢP NHẤT (P&L)
A3: TỔNG HỢP DOANH SỐ, LỢI NHUẬN TRƯỚC THUẾ • KỲ BÁO CÁO: THÁNG 06/2026 VÀ LŨY KẾ 6 THÁNG 2026
Q4: Đơn vị tính: Triệu đồng
A5: TT | B5: NỘI DUNG | C5: VỐN ĐT | D5: THÁNG 06 | K5: LŨY KẾ 6 THÁNG 2026
D6: DS | E6: % LG | F6: LG | G6: HT LG | H6: CHI PHÍ | I6: TN KHÁC | J6: LNTT | K6: DS | L6: % LG | M6: LG | N6: HT LG | O6: CHI PHÍ | P6: TN KHÁC | Q6: LNTT
A7: I | B7: MIỀN BẮC | C7: 90000 | D7: =D8+D18+D23+D24+D27 | E7: =IF(D7>0, F7/D7, 0) | F7: =F8+F18+F23+F24+F27 | G7: =G8+G18+G23+G24+G27 | H7: =H8+H18+H23+H24+H27 | I7: =I8+I18+I23+I24+I27 | J7: =J8+J18+J23+J24+J27 | K7: =K8+K18+K23+K24+K27 | L7: =IF(K7>0, M7/K7, 0) | M7: =M8+M18+M23+M24+M27 | N7: =N8+N18+N23+N24+N27 | O7: =O8+O18+O23+O24+O27 | P7: =P8+P18+P23+P24+P27 | Q7: ='Thang_05'!Q7+J7
A8: 1 | B8: THH (Tân Hồng Hà) | C8: 50000 | D8: =D9+D15+D16+D17 | E8: =IF(D8>0, F8/D8, 0) | F8: =F9+F15+F16+F17 | G8: =G9+G15+G16+G17 | H8: =H9+H15+H16+H17 | I8: =I9+I15+I16+I17 | J8: =J9+J15+J16+J17 | K8: =K9+K15+K16+K17 | L8: =IF(K8>0, M8/K8, 0) | M8: =M9+M15+M16+M17 | N8: =N9+N15+N16+N17 | O8: =O9+O15+O16+O17 | P8: =P9+P15+P16+P17 | Q8: ='Thang_05'!Q8+J8
A9: a | B9: Khối dịch vụ kỹ thuật | D9: =SUM(D10:D14) | E9: =IF(D9>0, F9/D9, 0) | F9: =SUM(F10:F14) | G9: =SUM(G10:G14) | H9: =SUM(H10:H14) | I9: =SUM(I10:I14) | J9: =F9+G9-H9+I9 | K9: =SUM(K10:K14) | L9: =IF(K9>0, M9/K9, 0) | M9: =SUM(M10:M14) | N9: =SUM(N10:N14) | O9: =SUM(O10:O14) | P9: =SUM(P10:P14) | Q9: ='Thang_05'!Q9+J9
A10: a.1 | B10: Tổ Dịch vụ | E10: =IF(D10>0, F10/D10, 0) | J10: =F10+G10-H10+I10 | K10: ='Thang_05'!K10+D10 | L10: =IF(K10>0, M10/K10, 0) | M10: ='Thang_05'!M10+F10 | N10: ='Thang_05'!N10+G10 | O10: ='Thang_05'!O10+H10 | P10: ='Thang_05'!P10+I10 | Q10: ='Thang_05'!Q10+J10
A11: a.2 | B11: Tổ mực in | E11: =IF(D11>0, F11/D11, 0) | J11: =F11+G11-H11+I11 | K11: ='Thang_05'!K11+D11 | L11: =IF(K11>0, M11/K11, 0) | M11: ='Thang_05'!M11+F11 | N11: ='Thang_05'!N11+G11 | O11: ='Thang_05'!O11+H11 | P11: ='Thang_05'!P11+I11 | Q11: ='Thang_05'!Q11+J11
A12: a.3 | B12: Thuê máy | E12: =IF(D12>0, F12/D12, 0) | J12: =F12+G12-H12+I12 | K12: ='Thang_05'!K12+D12 | L12: =IF(K12>0, M12/K12, 0) | M12: ='Thang_05'!M12+F12 | N12: ='Thang_05'!N12+G12 | O12: ='Thang_05'!O12+H12 | P12: ='Thang_05'!P12+I12 | Q12: ='Thang_05'!Q12+J12
A13: a.4 | B13: Metercharge | E13: =IF(D13>0, F13/D13, 0) | J13: =F13+G13-H13+I13 | K13: ='Thang_05'!K13+D13 | L13: =IF(K13>0, M13/K13, 0) | M13: ='Thang_05'!M13+F13 | N13: ='Thang_05'!N13+G13 | O13: ='Thang_05'!O13+H13 | P13: ='Thang_05'!P13+I13 | Q13: ='Thang_05'!Q13+J13
A14: a.5 | B14: Kinh doanh Online | E14: =IF(D14>0, F14/D14, 0) | J14: =F14+G14-H14+I14 | K14: ='Thang_05'!K14+D14 | L14: =IF(K14>0, M14/K14, 0) | M14: ='Thang_05'!M14+F14 | N14: ='Thang_05'!N14+G14 | O14: ='Thang_05'!O14+H14 | P14: ='Thang_05'!P14+I14 | Q14: ='Thang_05'!Q14+J14
A15: b | B15: Kinh doanh tổng hợp | E15: =IF(D15>0, F15/D15, 0) | J15: =F15+G15-H15+I15 | K15: ='Thang_05'!K15+D15 | L15: =IF(K15>0, M15/K15, 0) | M15: ='Thang_05'!M15+F15 | N15: ='Thang_05'!N15+G15 | O15: ='Thang_05'!O15+H15 | P15: ='Thang_05'!P15+I15 | Q15: ='Thang_05'!Q15+J15
A16: c | B16: Kinh doanh bán buôn | E16: =IF(D16>0, F16/D16, 0) | J16: =F16+G16-H16+I16 | K16: ='Thang_05'!K16+D16 | L16: =IF(K16>0, M16/K16, 0) | M16: ='Thang_05'!M16+F16 | N16: ='Thang_05'!N16+G16 | O16: ='Thang_05'!O16+H16 | P16: ='Thang_05'!P16+I16 | Q16: ='Thang_05'!Q16+J16
A17: d | B17: Dự án | E17: =IF(D17>0, F17/D17, 0) | J17: =F17+G17-H17+I17 | K17: ='Thang_05'!K17+D17 | L17: =IF(K17>0, M17/K17, 0) | M17: ='Thang_05'!M17+F17 | N17: ='Thang_05'!N17+G17 | O17: ='Thang_05'!O17+H17 | P17: ='Thang_05'!P17+I17 | Q17: ='Thang_05'!Q17+J17
A18: 2 | B18: Việt | C18: 10000 | D18: =SUM(D19:D22) | E18: =IF(D18>0, F18/D18, 0) | F18: =SUM(F19:F22) | G18: =SUM(G19:G22) | H18: =SUM(H19:H22) | I18: =SUM(I19:I22) | J18: =SUM(J19:J22) | K18: =SUM(K19:K22) | L18: =IF(K18>0, M18/K18, 0) | M18: =SUM(M19:M22) | N18: =SUM(N19:N22) | O18: =SUM(O19:O22) | P18: =SUM(P19:P22) | Q18: ='Thang_05'!Q18+J18
A19: 2.1 | B19: Thuê máy | E19: =IF(D19>0, F19/D19, 0) | J19: =F19+G19-H19+I19 | K19: ='Thang_05'!K19+D19 | L19: =IF(K19>0, M19/K19, 0) | M19: ='Thang_05'!M19+F19 | N19: ='Thang_05'!N19+G19 | O19: ='Thang_05'!O19+H19 | P19: ='Thang_05'!P19+I19 | Q19: ='Thang_05'!Q19+J19
A20: 2.2 | B20: KDTH | E20: =IF(D20>0, F20/D20, 0) | J20: =F20+G20-H20+I20 | K20: ='Thang_05'!K20+D20 | L20: =IF(K20>0, M20/K20, 0) | M20: ='Thang_05'!M20+F20 | N20: ='Thang_05'!N20+G20 | O20: ='Thang_05'!O20+H20 | P20: ='Thang_05'!P20+I20 | Q20: ='Thang_05'!Q20+J20
A21: 2.3 | B21: KD online | E21: =IF(D21>0, F21/D21, 0) | J21: =F21+G21-H21+I21 | K21: ='Thang_05'!K21+D21 | L21: =IF(K21>0, M21/K21, 0) | M21: ='Thang_05'!M21+F21 | N21: ='Thang_05'!N21+G21 | O21: ='Thang_05'!O21+H21 | P21: ='Thang_05'!P21+I21 | Q21: ='Thang_05'!Q21+J21
A22: 2.4 | B22: Cửa hàng | E22: =IF(D22>0, F22/D22, 0) | J22: =F22+G22-H22+I22 | K22: ='Thang_05'!K22+D22 | L22: =IF(K22>0, M22/K22, 0) | M22: ='Thang_05'!M22+F22 | N22: ='Thang_05'!N22+G22 | O22: ='Thang_05'!O22+H22 | P22: ='Thang_05'!P22+I22 | Q22: ='Thang_05'!Q22+J22
A23: 3 | B23: ITSS | C23: 5000 | E23: =IF(D23>0, F23/D23, 0) | J23: =F23+G23-H23+I23 | K23: ='Thang_05'!K23+D23 | L23: =IF(K23>0, M23/K23, 0) | M23: ='Thang_05'!M23+F23 | N23: ='Thang_05'!N23+G23 | O23: ='Thang_05'!O23+H23 | P23: ='Thang_05'!P23+I23 | Q23: ='Thang_05'!Q23+J23
A24: 4 | B24: CTY VPS | C24: 10000 | D24: =SUM(D25:D26) | E24: =IF(D24>0, F24/D24, 0) | F24: =SUM(F25:F26) | G24: =SUM(G25:G26) | H24: =SUM(H25:H26) | I24: =SUM(I25:I26) | J24: =SUM(J25:J26) | K24: =SUM(K25:K26) | L24: =IF(K24>0, M24/K24, 0) | M24: =SUM(M25:M26) | N24: =SUM(N25:N26) | O24: =SUM(O25:O26) | P24: =SUM(P25:P26) | Q24: ='Thang_05'!Q24+J24
A25: 4.1 | B25: VP VPS - hoạt động KD | E25: =IF(D25>0, F25/D25, 0) | J25: =F25+G25-H25+I25 | K25: ='Thang_05'!K25+D25 | L25: =IF(K25>0, M25/K25, 0) | M25: ='Thang_05'!M25+F25 | N25: ='Thang_05'!N25+G25 | O25: ='Thang_05'!O25+H25 | P25: ='Thang_05'!P25+I25 | Q25: ='Thang_05'!Q25+J25
A26: 4.2 | B26: HĐ đầu tư Tài chính | E26: =IF(D26>0, F26/D26, 0) | J26: =F26+G26-H26+I26 | K26: ='Thang_05'!K26+D26 | L26: =IF(K26>0, M26/K26, 0) | M26: ='Thang_05'!M26+F26 | N26: ='Thang_05'!N26+G26 | O26: ='Thang_05'!O26+H26 | P26: ='Thang_05'!P26+I26 | Q26: ='Thang_05'!Q26+J26
A27: 5 | B27: XESCO (Xem Sơn) | C27: 15000 | D27: =D28+D33 | E27: =IF(D27>0, F27/D27, 0) | F27: =F28+F33 | G27: =G28+G33 | H27: =H28+H33 | I27: =I28+I33 | J27: =J28+J33 | K27: =K28+K33 | L27: =IF(K27>0, M27/K27, 0) | M27: =M28+M33 | N27: =N28+N33 | O27: =O28+O33 | P27: =P28+P33 | Q27: ='Thang_05'!Q27+J27
A28: 5.1 | B28: Xesco - KD | D28: =SUM(D29:D32) | E28: =IF(D28>0, F28/D28, 0) | F28: =SUM(F29:F32) | G28: =SUM(G29:G32) | H28: =SUM(H29:H32) | I28: =SUM(I29:I32) | J28: =F28+G28-H28+I28 | K28: =SUM(K29:K32) | L28: =IF(K28>0, M28/K28, 0) | M28: =SUM(M29:M32) | N28: =SUM(N29:N32) | O28: =SUM(O29:O32) | P28: =SUM(P29:P32) | Q28: ='Thang_05'!Q28+J28
A29: • | B29: Bán máy lẻ | E29: =IF(D29>0, F29/D29, 0) | J29: =F29+G29-H29+I29 | K29: ='Thang_05'!K29+D29 | L29: =IF(K29>0, M29/K29, 0) | M29: ='Thang_05'!M29+F29 | N29: ='Thang_05'!N29+G29 | O29: ='Thang_05'!O29+H29 | P29: ='Thang_05'!P29+I29 | Q29: ='Thang_05'!Q29+J29
A30: • | B30: KD sỉ | E30: =IF(D30>0, F30/D30, 0) | J30: =F30+G30-H30+I30 | K30: ='Thang_05'!K30+D30 | L30: =IF(K30>0, M30/K30, 0) | M30: ='Thang_05'!M30+F30 | N30: ='Thang_05'!N30+G30 | O30: ='Thang_05'!O30+H30 | P30: ='Thang_05'!P30+I30 | Q30: ='Thang_05'!Q30+J30
A31: • | B31: KD Online | E31: =IF(D31>0, F31/D31, 0) | J31: =F31+G31-H31+I31 | K31: ='Thang_05'!K31+D31 | L31: =IF(K31>0, M31/K31, 0) | M31: ='Thang_05'!M31+F31 | N31: ='Thang_05'!N31+G31 | O31: ='Thang_05'!O31+H31 | P31: ='Thang_05'!P31+I31 | Q31: ='Thang_05'!Q31+J31
A32: • | B32: KD Thuê máy | E32: =IF(D32>0, F32/D32, 0) | J32: =F32+G32-H32+I32 | K32: ='Thang_05'!K32+D32 | L32: =IF(K32>0, M32/K32, 0) | M32: ='Thang_05'!M32+F32 | N32: ='Thang_05'!N32+G32 | O32: ='Thang_05'!O32+H32 | P32: ='Thang_05'!P32+I32 | Q32: ='Thang_05'!Q32+J32
A33: 5.2 | B33: Xesco - KT | D33: =SUM(D34:D36) | E33: =IF(D33>0, F33/D33, 0) | F33: =SUM(F34:F36) | G33: =SUM(G34:G36) | H33: =SUM(H34:H36) | I33: =SUM(I34:I36) | J33: =F33+G33-H33+I33 | K33: =SUM(K34:K36) | L33: =IF(K33>0, M33/K33, 0) | M33: =SUM(M34:M36) | N33: =SUM(N34:N36) | O33: =SUM(O34:O36) | P33: =SUM(P34:P36) | Q33: ='Thang_05'!Q33+J33
A34: • | B34: Thuê máy | E34: =IF(D34>0, F34/D34, 0) | J34: =F34+G34-H34+I34 | K34: ='Thang_05'!K34+D34 | L34: =IF(K34>0, M34/K34, 0) | M34: ='Thang_05'!M34+F34 | N34: ='Thang_05'!N34+G34 | O34: ='Thang_05'!O34+H34 | P34: ='Thang_05'!P34+I34 | Q34: ='Thang_05'!Q34+J34
A35: • | B35: Metercharge | E35: =IF(D35>0, F35/D35, 0) | J35: =F35+G35-H35+I35 | K35: ='Thang_05'!K35+D35 | L35: =IF(K35>0, M35/K35, 0) | M35: ='Thang_05'!M35+F35 | N35: ='Thang_05'!N35+G35 | O35: ='Thang_05'!O35+H35 | P35: ='Thang_05'!P35+I35 | Q35: ='Thang_05'!Q35+J35
A36: • | B36: Dịch vụ | E36: =IF(D36>0, F36/D36, 0) | J36: =F36+G36-H36+I36 | K36: ='Thang_05'!K36+D36 | L36: =IF(K36>0, M36/K36, 0) | M36: ='Thang_05'!M36+F36 | N36: ='Thang_05'!N36+G36 | O36: ='Thang_05'!O36+H36 | P36: ='Thang_05'!P36+I36 | Q36: ='Thang_05'!Q36+J36
A37: II | B37: VPS MIỀN TRUNG | C37: 3000 | D37: =SUM(D38:D44) | E37: =IF(D37>0, F37/D37, 0) | F37: =SUM(F38:F44) | G37: =SUM(G38:G44) | H37: =SUM(H38:H44) | I37: =SUM(I38:I44) | J37: =SUM(J38:J44) | K37: =SUM(K38:K44) | L37: =IF(K37>0, M37/K37, 0) | M37: =SUM(M38:M44) | N37: =SUM(N38:N44) | O37: =SUM(O38:O44) | P37: =SUM(P38:P44) | Q37: ='Thang_05'!Q37+J37
A38: • | B38: Kinh doanh máy - bán buôn | E38: =IF(D38>0, F38/D38, 0) | J38: =F38+G38-H38+I38 | K38: ='Thang_05'!K38+D38 | L38: =IF(K38>0, M38/K38, 0) | M38: ='Thang_05'!M38+F38 | N38: ='Thang_05'!N38+G38 | O38: ='Thang_05'!O38+H38 | P38: ='Thang_05'!P38+I38 | Q38: ='Thang_05'!Q38+J38
A39: • | B39: Kinh doanh linh kiện - bán buôn | E39: =IF(D39>0, F39/D39, 0) | J39: =F39+G39-H39+I39 | K39: ='Thang_05'!K39+D39 | L39: =IF(K39>0, M39/K39, 0) | M39: ='Thang_05'!M39+F39 | N39: ='Thang_05'!N39+G39 | O39: ='Thang_05'!O39+H39 | P39: ='Thang_05'!P39+I39 | Q39: ='Thang_05'!Q39+J39
A40: • | B40: Shopee-Online | E40: =IF(D40>0, F40/D40, 0) | J40: =F40+G40-H40+I40 | K40: ='Thang_05'!K40+D40 | L40: =IF(K40>0, M40/K40, 0) | M40: ='Thang_05'!M40+F40 | N40: ='Thang_05'!N40+G40 | O40: ='Thang_05'!O40+H40 | P40: ='Thang_05'!P40+I40 | Q40: ='Thang_05'!Q40+J40
...

Sheet Thang_07
A1: MÁY VĂN PHÒNG HÀNG ĐẦU VIỆT NAM - TẬP ĐOÀN VPS
A2: BÁO CÁO KẾT QUẢ KINH DOANH HỢP NHẤT (P&L)
A3: TỔNG HỢP DOANH SỐ, LỢI NHUẬN TRƯỚC THUẾ • KỲ BÁO CÁO: THÁNG 07/2026 VÀ LŨY KẾ 7 THÁNG 2026
Q4: Đơn vị tính: Triệu đồng
A5: TT | B5: NỘI DUNG | C5: VỐN ĐT | D5: THÁNG 07 | K5: LŨY KẾ 7 THÁNG 2026
D6: DS | E6: % LG | F6: LG | G6: HT LG | H6: CHI PHÍ | I6: TN KHÁC | J6: LNTT | K6: DS | L6: % LG | M6: LG | N6: HT LG | O6: CHI PHÍ | P6: TN KHÁC | Q6: LNTT
A7: I | B7: MIỀN BẮC | C7: 90000 | D7: 41454 | E7: 0.14642737 | F7: 6070 | G7: 5 | H7: 6865 | I7: 1095 | J7: -89 | K7: 197473 | L7: 0.2277881 | M7: 44982 | N7: 335 | O7: 49241 | P7: 7731 | Q7: -234
A8: 1 | B8: THH (Tân Hồng Hà) | C8: 50000 | D8: 8804 | E8: 0.17810086 | F8: 1568 | G8: 5 | H8: 1341 | I8: 8 | J8: 245 | K8: 66583 | L8: 0.15142003 | M8: 10082 | N8: 335 | O8: 12453 | P8: 57 | Q8: 2376
A9: a | B9: Khối dịch vụ kỹ thuật | D9: 2578 | E9: 0.33514352 | F9: 864 | H9: 798 | I9: 1 | J9: 67 | K9: 16145.6 | L9: 0.35594837 | M9: 5747 | N9: 54 | O9: 5516 | P9: 1 | Q9: 286
A10: a.1 | B10: Tổ Dịch vụ | D10: 1346 | E10: 0.25817236 | F10: 347.5 | H10: 260.5 | J10: 87 | K10: 8304.5 | L10: 0.33056776 | M10: 2745.2 | N10: 53 | O10: 2000 | Q10: 798.2
A11: a.2 | B11: Tổ mực in | D11: 292 | E11: 0.49554795 | F11: 144.7 | H11: 89.1 | J11: 55.6 | K11: 2054.6 | L11: 0.51494208 | M11: 1058 | O11: 600 | Q11: 458
A12: a.3 | B12: Thuê máy | D12: 605 | E12: 0.38198347 | F12: 231.1 | H12: 172.7 | J12: 58.4 | K12: 3654.1 | L12: 0.32629102 | M12: 1192.3 | O12: 900 | Q12: 292.3
A13: a.4 | B13: Metercharge | D13: 233 | E13: 0.60515021 | F13: 141 | H13: 81.6 | J13: 59.4 | K13: 1459.2 | L13: 0.50548246 | M13: 737.6 | O13: 450 | Q13: 287.6
A14: a.5 | B14: Kinh doanh Online | D14: 102 | E14: -0.0058823529 | F14: -0.6 | G14: 1 | H14: 2.4 | J14: -2 | K14: 673.4 | L14: 0.020938521 | M14: 14.1 | N14: 1 | O14: 12 | Q14: 3.1
A15: b | B15: Kinh doanh tổng hợp | D15: 1139 | E15: 0.15329236 | F15: 174.6 | H15: 165 | I15: 10 | J15: 19.6 | K15: 12937.5 | L15: 0.079976812 | M15: 1034.7 | N15: 9 | O15: 1157 | P15: 47 | Q15: -66
A16: c | B16: Kinh doanh bán buôn | D16: 4792 | E16: 0.098727045 | F16: 473.1 | G16: 5 | H16: 311 | I16: 7 | J16: 178 | K16: 35000 | L16: 0.065002857 | M16: 2275.1 | N16: 271 | O16: 2438 | P16: 10 | Q16: 119
A17: d | B17: Dự án | D17: 295 | E17: 0.19016949 | F17: 56.1 | H17: 67 | J17: -10 | K17: 2500 | L17: 0.41 | M17: 1025 | O17: 3342 | Q17: 2038
A18: 2 | B18: Việt | C18: 10000 | D18: 6848 | E18: 0.20297897 | F18: 1390 | G18: 0 | H18: 983 | I18: 7 | J18: 382 | K18: 40294 | L18: 0.21248821 | M18: 8562 | N18: 0 | O18: 6903 | P18: 13 | Q18: 1672
A19: 2.1 | B19: Thuê máy | D19: 1565 | E19: 0.59041534 | F19: 924 | H19: 653 | J19: 271 | K19: 10876 | L19: 0.5778779 | M19: 6285 | O19: 4513 | P19: 11.4 | Q19: 1783
A20: 2.2 | B20: KDTH | D20: 1991 | E20: 0.075841286 | F20: 151 | H20: 144 | I20: 7 | J20: 14 | K20: 12624 | L20: 0.076837769 | M20: 970 | O20: 1022 | P20: 1.5 | Q20: -51
A21: 2.3 | B21: KD online | D21: 3135 | E21: 0.067304625 | F21: 211 | H21: 149 | J21: 62 | K21: 16138 | L21: 0.061841616 | M21: 998 | O21: 1116 | Q21: -118
A22: 2.4 | B22: Cửa hàng | D22: 157 | E22: 0.49745223 | F22: 78.1 | H22: 37 | J22: 42 | K22: 656 | L22: 0.47256098 | M22: 310 | O22: 252 | Q22: 58
A23: 3 | B23: ITSS | C23: 5000 | D23: 524 | E23: 0.3740458 | F23: 196 | H23: 87 | I23: 4 | J23: 113 | K23: 2915 | L23: 0.35265866 | M23: 1028 | O23: 859 | P23: -4 | Q23: 165
A24: 4 | B24: CTY VPS | C24: 10000 | D24: 14951 | E24: 0.031168484 | F24: 466 | G24: 0 | H24: 2327 | I24: 1033 | J24: -828 | K24: 16633 | L24: 0.13755787 | M24: 2288 | N24: 0 | O24: 14400 | P24: 7665 | Q24: -4447
A25: 4.1 | B25: VP VPS - hoạt động KD | D25: 14951 | E25: 0.031168484 | F25: 466 | H25: 748 | I25: 419 | J25: 137 | K25: 16633 | L25: 0.13755787 | M25: 2288 | O25: 4673 | P25: 2732 | Q25: 347
A26: 4.2 | B26: HĐ đầu tư Tài chính | H26: 1579 | I26: 614 | J26: -965 | O26: 9727 | P26: 4933 | Q26: -4794
A27: 5 | B27: XESCO (Xem Sơn) | C27: 15000 | D27: 10326 | E27: 0.28200659 | F27: 2912 | G27: 0 | H27: 2129 | I27: 51 | J27: 834 | K27: 69425 | L27: 0.26888009 | M27: 18667 | N27: 0 | O27: 14626 | P27: 226 | Q27: 4267
A28: 5.1 | B28: Xesco - KD | D28: 7182 | E28: 0.16262879 | F28: 1168 | H28: 850 | J28: 318 | K28: 48562 | L28: 0.14680203 | M28: 7129 | O28: 5542 | P28: 100 | Q28: 1687
A29: • | B29: Bán máy lẻ | D29: 191 | E29: 0.2565445 | F29: 49 | H29: 71 | J29: -22 | K29: 3397 | L29: 0.22873123 | M29: 777 | O29: 601 | Q29: 176
A30: • | B30: KD sỉ | D30: 4032 | E30: 0.17113095 | F30: 690 | H30: 479 | J30: 211 | K30: 22834 | L30: 0.16322151 | M30: 3727 | O30: 3151 | P30: 100 | Q30: 676
A31: • | B31: KD Online | D31: 2539 | E31: 0.05317054 | F31: 135 | H31: 129 | J31: 6 | K31: 19679 | L31: 0.039077189 | M31: 769 | O31: 741 | Q31: 28
A32: • | B32: KD Thuê máy | D32: 420 | E32: 0.7 | F32: 294 | H32: 171 | J32: 123 | K32: 2653 | L32: 0.69958538 | M32: 1856 | O32: 1049 | Q32: 807
A33: 5.2 | B33: Xesco - KT | D33: 3144 | E33: 0.55470738 | F33: 1744 | H33: 1279 | J33: 465 | K33: 20863 | L33: 0.55303648 | M33: 11538 | O33: 9084 | P33: 126 | Q33: 2580
A34: • | B34: Thuê máy | D34: 1502 | E34: 0.66178429 | F34: 994 | H34: 776 | J34: 218 | K34: 10358 | L34: 0.6717513 | M34: 6958 | O34: 5723 | P34: 6 | Q34: 1241
A35: • | B35: Metercharge | D35: 278 | E35: 0.58992806 | F35: 164 | J35: 164 | K35: 1869 | L35: 0.59604066 | M35: 1114 | Q35: 1114
A36: • | B36: Dịch vụ | D36: 1364 | E36: 0.42961877 | F36: 586 | H36: 503 | J36: 83 | K36: 8636 | L36: 0.40134321 | M36: 3466 | O36: 3361 | P36: 120 | Q36: 225
A37: II | B37: VPS MIỀN TRUNG | C37: 3000 | D37: 1674 | E37: 0.1427718 | F37: 239 | G37: 0 | H37: 220 | I37: 66 | J37: 85 | K37: 11251 | L37: 0.2014932 | M37: 2267 | N37: 0 | O37: 1515 | P37: 76 | Q37: 828
A38: • | B38: Kinh doanh máy - bán buôn | D38: 993 | E38: 0.049345418 | F38: 49 | H38: 40 | J38: 9 | K38: 5840 | L38: 0.084931507 | M38: 496 | O38: 320 | Q38: 176
A39: • | B39: Kinh doanh linh kiện - bán buôn | D39: 231 | E39: 0.14285714 | F39: 33 | H39: 25 | J39: 8 | K39: 1788 | L39: 0.14988814 | M39: 268 | O39: 180 | Q39: 88
A40: • | B40: Shopee-Online | D40: 93 | E40: 0.021505376 | F40: 2 | H40: 5 | J40: -3 | K40: 806 | L40: 0.055831266 | M40: 45 | O40: 35 | Q40: 10
...

Sheet Thang_08
A1: MÁY VĂN PHÒNG HÀNG ĐẦU VIỆT NAM - TẬP ĐOÀN VPS
A2: BÁO CÁO KẾT QUẢ KINH DOANH HỢP NHẤT (P&L)
A3: TỔNG HỢP DOANH SỐ, LỢI NHUẬN TRƯỚC THUẾ • KỲ BÁO CÁO: THÁNG 08/2026 VÀ LŨY KẾ 8 THÁNG 2026
Q4: Đơn vị tính: Triệu đồng
A5: TT | B5: NỘI DUNG | C5: VỐN ĐT | D5: THÁNG 08 | K5: LŨY KẾ 8 THÁNG 2026
D6: DS | E6: % LG | F6: LG | G6: HT LG | H6: CHI PHÍ | I6: TN KHÁC | J6: LNTT | K6: DS | L6: % LG | M6: LG | N6: HT LG | O6: CHI PHÍ | P6: TN KHÁC | Q6: LNTT
A7: I | B7: MIỀN BẮC | C7: 90000 | D7: =D8+D18+D23+D24+D27 | E7: =IF(D7>0, F7/D7, 0) | F7: =F8+F18+F23+F24+F27 | G7: =G8+G18+G23+G24+G27 | H7: =H8+H18+H23+H24+H27 | I7: =I8+I18+I23+I24+I27 | J7: =J8+J18+J23+J24+J27 | K7: =K8+K18+K23+K24+K27 | L7: =IF(K7>0, M7/K7, 0) | M7: =M8+M18+M23+M24+M27 | N7: =N8+N18+N23+N24+N27 | O7: =O8+O18+O23+O24+O27 | P7: =P8+P18+P23+P24+P27 | Q7: ='Thang_07'!Q7+J7
A8: 1 | B8: THH (Tân Hồng Hà) | C8: 50000 | D8: =D9+D15+D16+D17 | E8: =IF(D8>0, F8/D8, 0) | F8: =F9+F15+F16+F17 | G8: =G9+G15+G16+G17 | H8: =H9+H15+H16+H17 | I8: =I9+I15+I16+I17 | J8: =J9+J15+J16+J17 | K8: =K9+K15+K16+K17 | L8: =IF(K8>0, M8/K8, 0) | M8: =M9+M15+M16+M17 | N8: =N9+N15+N16+N17 | O8: =O9+O15+O16+O17 | P8: =P9+P15+P16+P17 | Q8: ='Thang_07'!Q8+J8
A9: a | B9: Khối dịch vụ kỹ thuật | D9: =SUM(D10:D14) | E9: =IF(D9>0, F9/D9, 0) | F9: =SUM(F10:F14) | G9: =SUM(G10:G14) | H9: =SUM(H10:H14) | I9: =SUM(I10:I14) | J9: =F9+G9-H9+I9 | K9: =SUM(K10:K14) | L9: =IF(K9>0, M9/K9, 0) | M9: =SUM(M10:M14) | N9: =SUM(N10:N14) | O9: =SUM(O10:O14) | P9: =SUM(P10:P14) | Q9: ='Thang_07'!Q9+J9
A10: a.1 | B10: Tổ Dịch vụ | E10: =IF(D10>0, F10/D10, 0) | J10: =F10+G10-H10+I10 | K10: ='Thang_07'!K10+D10 | L10: =IF(K10>0, M10/K10, 0) | M10: ='Thang_07'!M10+F10 | N10: ='Thang_07'!N10+G10 | O10: ='Thang_07'!O10+H10 | P10: ='Thang_07'!P10+I10 | Q10: ='Thang_07'!Q10+J10
A11: a.2 | B11: Tổ mực in | E11: =IF(D11>0, F11/D11, 0) | J11: =F11+G11-H11+I11 | K11: ='Thang_07'!K11+D11 | L11: =IF(K11>0, M11/K11, 0) | M11: ='Thang_07'!M11+F11 | N11: ='Thang_07'!N11+G11 | O11: ='Thang_07'!O11+H11 | P11: ='Thang_07'!P11+I11 | Q11: ='Thang_07'!Q11+J11
A12: a.3 | B12: Thuê máy | E12: =IF(D12>0, F12/D12, 0) | J12: =F12+G12-H12+I12 | K12: ='Thang_07'!K12+D12 | L12: =IF(K12>0, M12/K12, 0) | M12: ='Thang_07'!M12+F12 | N12: ='Thang_07'!N12+G12 | O12: ='Thang_07'!O12+H12 | P12: ='Thang_07'!P12+I12 | Q12: ='Thang_07'!Q12+J12
A13: a.4 | B13: Metercharge | E13: =IF(D13>0, F13/D13, 0) | J13: =F13+G13-H13+I13 | K13: ='Thang_07'!K13+D13 | L13: =IF(K13>0, M13/K13, 0) | M13: ='Thang_07'!M13+F13 | N13: ='Thang_07'!N13+G13 | O13: ='Thang_07'!O13+H13 | P13: ='Thang_07'!P13+I13 | Q13: ='Thang_07'!Q13+J13
A14: a.5 | B14: Kinh doanh Online | E14: =IF(D14>0, F14/D14, 0) | J14: =F14+G14-H14+I14 | K14: ='Thang_07'!K14+D14 | L14: =IF(K14>0, M14/K14, 0) | M14: ='Thang_07'!M14+F14 | N14: ='Thang_07'!N14+G14 | O14: ='Thang_07'!O14+H14 | P14: ='Thang_07'!P14+I14 | Q14: ='Thang_07'!Q14+J14
A15: b | B15: Kinh doanh tổng hợp | E15: =IF(D15>0, F15/D15, 0) | J15: =F15+G15-H15+I15 | K15: ='Thang_07'!K15+D15 | L15: =IF(K15>0, M15/K15, 0) | M15: ='Thang_07'!M15+F15 | N15: ='Thang_07'!N15+G15 | O15: ='Thang_07'!O15+H15 | P15: ='Thang_07'!P15+I15 | Q15: ='Thang_07'!Q15+J15
A16: c | B16: Kinh doanh bán buôn | E16: =IF(D16>0, F16/D16, 0) | J16: =F16+G16-H16+I16 | K16: ='Thang_07'!K16+D16 | L16: =IF(K16>0, M16/K16, 0) | M16: ='Thang_07'!M16+F16 | N16: ='Thang_07'!N16+G16 | O16: ='Thang_07'!O16+H16 | P16: ='Thang_07'!P16+I16 | Q16: ='Thang_07'!Q16+J16
A17: d | B17: Dự án | E17: =IF(D17>0, F17/D17, 0) | J17: =F17+G17-H17+I17 | K17: ='Thang_07'!K17+D17 | L17: =IF(K17>0, M17/K17, 0) | M17: ='Thang_07'!M17+F17 | N17: ='Thang_07'!N17+G17 | O17: ='Thang_07'!O17+H17 | P17: ='Thang_07'!P17+I17 | Q17: ='Thang_07'!Q17+J17
A18: 2 | B18: Việt | C18: 10000 | D18: =SUM(D19:D22) | E18: =IF(D18>0, F18/D18, 0) | F18: =SUM(F19:F22) | G18: =SUM(G19:G22) | H18: =SUM(H19:H22) | I18: =SUM(I19:I22) | J18: =SUM(J19:J22) | K18: =SUM(K19:K22) | L18: =IF(K18>0, M18/K18, 0) | M18: =SUM(M19:M22) | N18: =SUM(N19:N22) | O18: =SUM(O19:O22) | P18: =SUM(P19:P22) | Q18: ='Thang_07'!Q18+J18
A19: 2.1 | B19: Thuê máy | E19: =IF(D19>0, F19/D19, 0) | J19: =F19+G19-H19+I19 | K19: ='Thang_07'!K19+D19 | L19: =IF(K19>0, M19/K19, 0) | M19: ='Thang_07'!M19+F19 | N19: ='Thang_07'!N19+G19 | O19: ='Thang_07'!O19+H19 | P19: ='Thang_07'!P19+I19 | Q19: ='Thang_07'!Q19+J19
A20: 2.2 | B20: KDTH | E20: =IF(D20>0, F20/D20, 0) | J20: =F20+G20-H20+I20 | K20: ='Thang_07'!K20+D20 | L20: =IF(K20>0, M20/K20, 0) | M20: ='Thang_07'!M20+F20 | N20: ='Thang_07'!N20+G20 | O20: ='Thang_07'!O20+H20 | P20: ='Thang_07'!P20+I20 | Q20: ='Thang_07'!Q20+J20
A21: 2.3 | B21: KD online | E21: =IF(D21>0, F21/D21, 0) | J21: =F21+G21-H21+I21 | K21: ='Thang_07'!K21+D21 | L21: =IF(K21>0, M21/K21, 0) | M21: ='Thang_07'!M21+F21 | N21: ='Thang_07'!N21+G21 | O21: ='Thang_07'!O21+H21 | P21: ='Thang_07'!P21+I21 | Q21: ='Thang_07'!Q21+J21
A22: 2.4 | B22: Cửa hàng | E22: =IF(D22>0, F22/D22, 0) | J22: =F22+G22-H22+I22 | K22: ='Thang_07'!K22+D22 | L22: =IF(K22>0, M22/K22, 0) | M22: ='Thang_07'!M22+F22 | N22: ='Thang_07'!N22+G22 | O22: ='Thang_07'!O22+H22 | P22: ='Thang_07'!P22+I22 | Q22: ='Thang_07'!Q22+J22
A23: 3 | B23: ITSS | C23: 5000 | E23: =IF(D23>0, F23/D23, 0) | J23: =F23+G23-H23+I23 | K23: ='Thang_07'!K23+D23 | L23: =IF(K23>0, M23/K23, 0) | M23: ='Thang_07'!M23+F23 | N23: ='Thang_07'!N23+G23 | O23: ='Thang_07'!O23+H23 | P23: ='Thang_07'!P23+I23 | Q23: ='Thang_07'!Q23+J23
A24: 4 | B24: CTY VPS | C24: 10000 | D24: =SUM(D25:D26) | E24: =IF(D24>0, F24/D24, 0) | F24: =SUM(F25:F26) | G24: =SUM(G25:G26) | H24: =SUM(H25:H26) | I24: =SUM(I25:I26) | J24: =SUM(J25:J26) | K24: =SUM(K25:K26) | L24: =IF(K24>0, M24/K24, 0) | M24: =SUM(M25:M26) | N24: =SUM(N25:N26) | O24: =SUM(O25:O26) | P24: =SUM(P25:P26) | Q24: ='Thang_07'!Q24+J24
A25: 4.1 | B25: VP VPS - hoạt động KD | E25: =IF(D25>0, F25/D25, 0) | J25: =F25+G25-H25+I25 | K25: ='Thang_07'!K25+D25 | L25: =IF(K25>0, M25/K25, 0) | M25: ='Thang_07'!M25+F25 | N25: ='Thang_07'!N25+G25 | O25: ='Thang_07'!O25+H25 | P25: ='Thang_07'!P25+I25 | Q25: ='Thang_07'!Q25+J25
A26: 4.2 | B26: HĐ đầu tư Tài chính | E26: =IF(D26>0, F26/D26, 0) | J26: =F26+G26-H26+I26 | K26: ='Thang_07'!K26+D26 | L26: =IF(K26>0, M26/K26, 0) | M26: ='Thang_07'!M26+F26 | N26: ='Thang_07'!N26+G26 | O26: ='Thang_07'!O26+H26 | P26: ='Thang_07'!P26+I26 | Q26: ='Thang_07'!Q26+J26
A27: 5 | B27: XESCO (Xem Sơn) | C27: 15000 | D27: =D28+D33 | E27: =IF(D27>0, F27/D27, 0) | F27: =F28+F33 | G27: =G28+G33 | H27: =H28+H33 | I27: =I28+I33 | J27: =J28+J33 | K27: =K28+K33 | L27: =IF(K27>0, M27/K27, 0) | M27: =M28+M33 | N27: =N28+N33 | O27: =O28+O33 | P27: =P28+P33 | Q27: ='Thang_07'!Q27+J27
A28: 5.1 | B28: Xesco - KD | D28: =SUM(D29:D32) | E28: =IF(D28>0, F28/D28, 0) | F28: =SUM(F29:F32) | G28: =SUM(G29:G32) | H28: =SUM(H29:H32) | I28: =SUM(I29:I32) | J28: =F28+G28-H28+I28 | K28: =SUM(K29:K32) | L28: =IF(K28>0, M28/K28, 0) | M28: =SUM(M29:M32) | N28: =SUM(N29:N32) | O28: =SUM(O29:O32) | P28: =SUM(P29:P32) | Q28: ='Thang_07'!Q28+J28
A29: • | B29: Bán máy lẻ | E29: =IF(D29>0, F29/D29, 0) | J29: =F29+G29-H29+I29 | K29: ='Thang_07'!K29+D29 | L29: =IF(K29>0, M29/K29, 0) | M29: ='Thang_07'!M29+F29 | N29: ='Thang_07'!N29+G29 | O29: ='Thang_07'!O29+H29 | P29: ='Thang_07'!P29+I29 | Q29: ='Thang_07'!Q29+J29
A30: • | B30: KD sỉ | E30: =IF(D30>0, F30/D30, 0) | J30: =F30+G30-H30+I30 | K30: ='Thang_07'!K30+D30 | L30: =IF(K30>0, M30/K30, 0) | M30: ='Thang_07'!M30+F30 | N30: ='Thang_07'!N30+G30 | O30: ='Thang_07'!O30+H30 | P30: ='Thang_07'!P30+I30 | Q30: ='Thang_07'!Q30+J30
A31: • | B31: KD Online | E31: =IF(D31>0, F31/D31, 0) | J31: =F31+G31-H31+I31 | K31: ='Thang_07'!K31+D31 | L31: =IF(K31>0, M31/K31, 0) | M31: ='Thang_07'!M31+F31 | N31: ='Thang_07'!N31+G31 | O31: ='Thang_07'!O31+H31 | P31: ='Thang_07'!P31+I31 | Q31: ='Thang_07'!Q31+J31
A32: • | B32: KD Thuê máy | E32: =IF(D32>0, F32/D32, 0) | J32: =F32+G32-H32+I32 | K32: ='Thang_07'!K32+D32 | L32: =IF(K32>0, M32/K32, 0) | M32: ='Thang_07'!M32+F32 | N32: ='Thang_07'!N32+G32 | O32: ='Thang_07'!O32+H32 | P32: ='Thang_07'!P32+I32 | Q32: ='Thang_07'!Q32+J32
A33: 5.2 | B33: Xesco - KT | D33: =SUM(D34:D36) | E33: =IF(D33>0, F33/D33, 0) | F33: =SUM(F34:F36) | G33: =SUM(G34:G36) | H33: =SUM(H34:H36) | I33: =SUM(I34:I36) | J33: =F33+G33-H33+I33 | K33: =SUM(K34:K36) | L33: =IF(K33>0, M33/K33, 0) | M33: =SUM(M34:M36) | N33: =SUM(N34:N36) | O33: =SUM(O34:O36) | P33: =SUM(P34:P36) | Q33: ='Thang_07'!Q33+J33
A34: • | B34: Thuê máy | E34: =IF(D34>0, F34/D34, 0) | J34: =F34+G34-H34+I34 | K34: ='Thang_07'!K34+D34 | L34: =IF(K34>0, M34/K34, 0) | M34: ='Thang_07'!M34+F34 | N34: ='Thang_07'!N34+G34 | O34: ='Thang_07'!O34+H34 | P34: ='Thang_07'!P34+I34 | Q34: ='Thang_07'!Q34+J34
A35: • | B35: Metercharge | E35: =IF(D35>0, F35/D35, 0) | J35: =F35+G35-H35+I35 | K35: ='Thang_07'!K35+D35 | L35: =IF(K35>0, M35/K35, 0) | M35: ='Thang_07'!M35+F35 | N35: ='Thang_07'!N35+G35 | O35: ='Thang_07'!O35+H35 | P35: ='Thang_07'!P35+I35 | Q35: ='Thang_07'!Q35+J35
A36: • | B36: Dịch vụ | E36: =IF(D36>0, F36/D36, 0) | J36: =F36+G36-H36+I36 | K36: ='Thang_07'!K36+D36 | L36: =IF(K36>0, M36/K36, 0) | M36: ='Thang_07'!M36+F36 | N36: ='Thang_07'!N36+G36 | O36: ='Thang_07'!O36+H36 | P36: ='Thang_07'!P36+I36 | Q36: ='Thang_07'!Q36+J36
A37: II | B37: VPS MIỀN TRUNG | C37: 3000 | D37: =SUM(D38:D44) | E37: =IF(D37>0, F37/D37, 0) | F37: =SUM(F38:F44) | G37: =SUM(G38:G44) | H37: =SUM(H38:H44) | I37: =SUM(I38:I44) | J37: =SUM(J38:J44) | K37: =SUM(K38:K44) | L37: =IF(K37>0, M37/K37, 0) | M37: =SUM(M38:M44) | N37: =SUM(N38:N44) | O37: =SUM(O38:O44) | P37: =SUM(P38:P44) | Q37: ='Thang_07'!Q37+J37
A38: • | B38: Kinh doanh máy - bán buôn | E38: =IF(D38>0, F38/D38, 0) | J38: =F38+G38-H38+I38 | K38: ='Thang_07'!K38+D38 | L38: =IF(K38>0, M38/K38, 0) | M38: ='Thang_07'!M38+F38 | N38: ='Thang_07'!N38+G38 | O38: ='Thang_07'!O38+H38 | P38: ='Thang_07'!P38+I38 | Q38: ='Thang_07'!Q38+J38
