Workbook

Sheet Thang_09
A1: BÁO CÁO KẾT QUẢ HOẠT ĐỘNG KINH DOANH - THÁNG 09/2026
A2: Đơn vị tính: Triệu đồng (Tr.đ) | Tự động cộng dồn lũy kế kế thừa Tháng 08 | Đồng bộ trực tiếp Dashboard VPS Group
A3: TT | B3: NỘI DUNG / ĐƠN VỊ KINH DOANH | C3: VỐN ĐT | D3: PHÁT SINH THÁNG 09/2026 | L3: LŨY KẾ ĐẾN HẾT THÁNG 09/2026
D4: DS | E4: % LG | F4: LG | G4: HT LG | H4: CHI PHÍ | I4: TN KHÁC | J4: CP KHÁC | K4: LNTT | L4: DS | M4: % LG | N4: LG | O4: HT LG | P4: CHI PHÍ | Q4: TN KHÁC | R4: LNTT
A5: I | B5: MIỀN BẮC | C5: 90000 | E5: =IF(D5>0, F5/D5, 0) | K5: =F5+G5-H5+I5-J5 | L5: =Moc_Luy_Ke_T8_Chot_So!D5+D5 | M5: =IF(L5>0, N5/L5, 0) | N5: =Moc_Luy_Ke_T8_Chot_So!F5+F5 | O5: =Moc_Luy_Ke_T8_Chot_So!G5+G5 | P5: =Moc_Luy_Ke_T8_Chot_So!H5+H5 | Q5: =Moc_Luy_Ke_T8_Chot_So!I5+I5-J5 | R5: =Moc_Luy_Ke_T8_Chot_So!J5+K5
A6: 1 | B6: THH (Tân Hồng Hà) | C6: 50000 | E6: =IF(D6>0, F6/D6, 0) | K6: =F6+G6-H6+I6-J6 | L6: =Moc_Luy_Ke_T8_Chot_So!D6+D6 | M6: =IF(L6>0, N6/L6, 0) | N6: =Moc_Luy_Ke_T8_Chot_So!F6+F6 | O6: =Moc_Luy_Ke_T8_Chot_So!G6+G6 | P6: =Moc_Luy_Ke_T8_Chot_So!H6+H6 | Q6: =Moc_Luy_Ke_T8_Chot_So!I6+I6-J6 | R6: =Moc_Luy_Ke_T8_Chot_So!J6+K6
A7: a | B7: Khối dịch vụ kỹ thuật | E7: =IF(D7>0, F7/D7, 0) | K7: =F7+G7-H7+I7-J7 | L7: =Moc_Luy_Ke_T8_Chot_So!D7+D7 | M7: =IF(L7>0, N7/L7, 0) | N7: =Moc_Luy_Ke_T8_Chot_So!F7+F7 | O7: =Moc_Luy_Ke_T8_Chot_So!G7+G7 | P7: =Moc_Luy_Ke_T8_Chot_So!H7+H7 | Q7: =Moc_Luy_Ke_T8_Chot_So!I7+I7-J7 | R7: =Moc_Luy_Ke_T8_Chot_So!J7+K7
A8: a.1 | B8: Tổ Dịch vụ | E8: =IF(D8>0, F8/D8, 0) | K8: =F8+G8-H8+I8-J8 | L8: =Moc_Luy_Ke_T8_Chot_So!D8+D8 | M8: =IF(L8>0, N8/L8, 0) | N8: =Moc_Luy_Ke_T8_Chot_So!F8+F8 | O8: =Moc_Luy_Ke_T8_Chot_So!G8+G8 | P8: =Moc_Luy_Ke_T8_Chot_So!H8+H8 | Q8: =Moc_Luy_Ke_T8_Chot_So!I8+I8-J8 | R8: =Moc_Luy_Ke_T8_Chot_So!J8+K8
A9: a.2 | B9: Tổ mực in | E9: =IF(D9>0, F9/D9, 0) | K9: =F9+G9-H9+I9-J9 | L9: =Moc_Luy_Ke_T8_Chot_So!D9+D9 | M9: =IF(L9>0, N9/L9, 0) | N9: =Moc_Luy_Ke_T8_Chot_So!F9+F9 | O9: =Moc_Luy_Ke_T8_Chot_So!G9+G9 | P9: =Moc_Luy_Ke_T8_Chot_So!H9+H9 | Q9: =Moc_Luy_Ke_T8_Chot_So!I9+I9-J9 | R9: =Moc_Luy_Ke_T8_Chot_So!J9+K9
A10: a.3 | B10: Thuê máy | E10: =IF(D10>0, F10/D10, 0) | K10: =F10+G10-H10+I10-J10 | L10: =Moc_Luy_Ke_T8_Chot_So!D10+D10 | M10: =IF(L10>0, N10/L10, 0) | N10: =Moc_Luy_Ke_T8_Chot_So!F10+F10 | O10: =Moc_Luy_Ke_T8_Chot_So!G10+G10 | P10: =Moc_Luy_Ke_T8_Chot_So!H10+H10 | Q10: =Moc_Luy_Ke_T8_Chot_So!I10+I10-J10 | R10: =Moc_Luy_Ke_T8_Chot_So!J10+K10
A11: a.4 | B11: Metercharge | E11: =IF(D11>0, F11/D11, 0) | K11: =F11+G11-H11+I11-J11 | L11: =Moc_Luy_Ke_T8_Chot_So!D11+D11 | M11: =IF(L11>0, N11/L11, 0) | N11: =Moc_Luy_Ke_T8_Chot_So!F11+F11 | O11: =Moc_Luy_Ke_T8_Chot_So!G11+G11 | P11: =Moc_Luy_Ke_T8_Chot_So!H11+H11 | Q11: =Moc_Luy_Ke_T8_Chot_So!I11+I11-J11 | R11: =Moc_Luy_Ke_T8_Chot_So!J11+K11
A12: a.5 | B12: Kinh doanh Online | E12: =IF(D12>0, F12/D12, 0) | K12: =F12+G12-H12+I12-J12 | L12: =Moc_Luy_Ke_T8_Chot_So!D12+D12 | M12: =IF(L12>0, N12/L12, 0) | N12: =Moc_Luy_Ke_T8_Chot_So!F12+F12 | O12: =Moc_Luy_Ke_T8_Chot_So!G12+G12 | P12: =Moc_Luy_Ke_T8_Chot_So!H12+H12 | Q12: =Moc_Luy_Ke_T8_Chot_So!I12+I12-J12 | R12: =Moc_Luy_Ke_T8_Chot_So!J12+K12
A13: b | B13: Kinh doanh tổng hợp | E13: =IF(D13>0, F13/D13, 0) | K13: =F13+G13-H13+I13-J13 | L13: =Moc_Luy_Ke_T8_Chot_So!D13+D13 | M13: =IF(L13>0, N13/L13, 0) | N13: =Moc_Luy_Ke_T8_Chot_So!F13+F13 | O13: =Moc_Luy_Ke_T8_Chot_So!G13+G13 | P13: =Moc_Luy_Ke_T8_Chot_So!H13+H13 | Q13: =Moc_Luy_Ke_T8_Chot_So!I13+I13-J13 | R13: =Moc_Luy_Ke_T8_Chot_So!J13+K13
A14: c | B14: Kinh doanh bán buôn | E14: =IF(D14>0, F14/D14, 0) | K14: =F14+G14-H14+I14-J14 | L14: =Moc_Luy_Ke_T8_Chot_So!D14+D14 | M14: =IF(L14>0, N14/L14, 0) | N14: =Moc_Luy_Ke_T8_Chot_So!F14+F14 | O14: =Moc_Luy_Ke_T8_Chot_So!G14+G14 | P14: =Moc_Luy_Ke_T8_Chot_So!H14+H14 | Q14: =Moc_Luy_Ke_T8_Chot_So!I14+I14-J14 | R14: =Moc_Luy_Ke_T8_Chot_So!J14+K14
A15: d | B15: Dự án | E15: =IF(D15>0, F15/D15, 0) | K15: =F15+G15-H15+I15-J15 | L15: =Moc_Luy_Ke_T8_Chot_So!D15+D15 | M15: =IF(L15>0, N15/L15, 0) | N15: =Moc_Luy_Ke_T8_Chot_So!F15+F15 | O15: =Moc_Luy_Ke_T8_Chot_So!G15+G15 | P15: =Moc_Luy_Ke_T8_Chot_So!H15+H15 | Q15: =Moc_Luy_Ke_T8_Chot_So!I15+I15-J15 | R15: =Moc_Luy_Ke_T8_Chot_So!J15+K15
A16: 2 | B16: Việt | C16: 10000 | E16: =IF(D16>0, F16/D16, 0) | K16: =F16+G16-H16+I16-J16 | L16: =Moc_Luy_Ke_T8_Chot_So!D16+D16 | M16: =IF(L16>0, N16/L16, 0) | N16: =Moc_Luy_Ke_T8_Chot_So!F16+F16 | O16: =Moc_Luy_Ke_T8_Chot_So!G16+G16 | P16: =Moc_Luy_Ke_T8_Chot_So!H16+H16 | Q16: =Moc_Luy_Ke_T8_Chot_So!I16+I16-J16 | R16: =Moc_Luy_Ke_T8_Chot_So!J16+K16
A17: 2.1 | B17: Thuê máy | E17: =IF(D17>0, F17/D17, 0) | K17: =F17+G17-H17+I17-J17 | L17: =Moc_Luy_Ke_T8_Chot_So!D17+D17 | M17: =IF(L17>0, N17/L17, 0) | N17: =Moc_Luy_Ke_T8_Chot_So!F17+F17 | O17: =Moc_Luy_Ke_T8_Chot_So!G17+G17 | P17: =Moc_Luy_Ke_T8_Chot_So!H17+H17 | Q17: =Moc_Luy_Ke_T8_Chot_So!I17+I17-J17 | R17: =Moc_Luy_Ke_T8_Chot_So!J17+K17
A18: 2.2 | B18: KDTH | E18: =IF(D18>0, F18/D18, 0) | K18: =F18+G18-H18+I18-J18 | L18: =Moc_Luy_Ke_T8_Chot_So!D18+D18 | M18: =IF(L18>0, N18/L18, 0) | N18: =Moc_Luy_Ke_T8_Chot_So!F18+F18 | O18: =Moc_Luy_Ke_T8_Chot_So!G18+G18 | P18: =Moc_Luy_Ke_T8_Chot_So!H18+H18 | Q18: =Moc_Luy_Ke_T8_Chot_So!I18+I18-J18 | R18: =Moc_Luy_Ke_T8_Chot_So!J18+K18
A19: 2.3 | B19: KD online | E19: =IF(D19>0, F19/D19, 0) | K19: =F19+G19-H19+I19-J19 | L19: =Moc_Luy_Ke_T8_Chot_So!D19+D19 | M19: =IF(L19>0, N19/L19, 0) | N19: =Moc_Luy_Ke_T8_Chot_So!F19+F19 | O19: =Moc_Luy_Ke_T8_Chot_So!G19+G19 | P19: =Moc_Luy_Ke_T8_Chot_So!H19+H19 | Q19: =Moc_Luy_Ke_T8_Chot_So!I19+I19-J19 | R19: =Moc_Luy_Ke_T8_Chot_So!J19+K19
A20: 2.4 | B20: Cửa hàng | E20: =IF(D20>0, F20/D20, 0) | K20: =F20+G20-H20+I20-J20 | L20: =Moc_Luy_Ke_T8_Chot_So!D20+D20 | M20: =IF(L20>0, N20/L20, 0) | N20: =Moc_Luy_Ke_T8_Chot_So!F20+F20 | O20: =Moc_Luy_Ke_T8_Chot_So!G20+G20 | P20: =Moc_Luy_Ke_T8_Chot_So!H20+H20 | Q20: =Moc_Luy_Ke_T8_Chot_So!I20+I20-J20 | R20: =Moc_Luy_Ke_T8_Chot_So!J20+K20
A21: 2.5 | B21: Nội bộ | E21: =IF(D21>0, F21/D21, 0) | K21: =F21+G21-H21+I21-J21 | L21: =Moc_Luy_Ke_T8_Chot_So!D21+D21 | M21: =IF(L21>0, N21/L21, 0) | N21: =Moc_Luy_Ke_T8_Chot_So!F21+F21 | O21: =Moc_Luy_Ke_T8_Chot_So!G21+G21 | P21: =Moc_Luy_Ke_T8_Chot_So!H21+H21 | Q21: =Moc_Luy_Ke_T8_Chot_So!I21+I21-J21 | R21: =Moc_Luy_Ke_T8_Chot_So!J21+K21
A22: 3 | B22: ITSS | C22: 5000 | E22: =IF(D22>0, F22/D22, 0) | K22: =F22+G22-H22+I22-J22 | L22: =Moc_Luy_Ke_T8_Chot_So!D22+D22 | M22: =IF(L22>0, N22/L22, 0) | N22: =Moc_Luy_Ke_T8_Chot_So!F22+F22 | O22: =Moc_Luy_Ke_T8_Chot_So!G22+G22 | P22: =Moc_Luy_Ke_T8_Chot_So!H22+H22 | Q22: =Moc_Luy_Ke_T8_Chot_So!I22+I22-J22 | R22: =Moc_Luy_Ke_T8_Chot_So!J22+K22
A23: 4 | B23: CTY VPS | C23: 10000 | E23: =IF(D23>0, F23/D23, 0) | K23: =F23+G23-H23+I23-J23 | L23: =Moc_Luy_Ke_T8_Chot_So!D23+D23 | M23: =IF(L23>0, N23/L23, 0) | N23: =Moc_Luy_Ke_T8_Chot_So!F23+F23 | O23: =Moc_Luy_Ke_T8_Chot_So!G23+G23 | P23: =Moc_Luy_Ke_T8_Chot_So!H23+H23 | Q23: =Moc_Luy_Ke_T8_Chot_So!I23+I23-J23 | R23: =Moc_Luy_Ke_T8_Chot_So!J23+K23
A24: 4.1 | B24: VP VPS - hoạt động KD | E24: =IF(D24>0, F24/D24, 0) | K24: =F24+G24-H24+I24-J24 | L24: =Moc_Luy_Ke_T8_Chot_So!D24+D24 | M24: =IF(L24>0, N24/L24, 0) | N24: =Moc_Luy_Ke_T8_Chot_So!F24+F24 | O24: =Moc_Luy_Ke_T8_Chot_So!G24+G24 | P24: =Moc_Luy_Ke_T8_Chot_So!H24+H24 | Q24: =Moc_Luy_Ke_T8_Chot_So!I24+I24-J24 | R24: =Moc_Luy_Ke_T8_Chot_So!J24+K24
A25: • | B25: VPS bán nội bộ | E25: =IF(D25>0, F25/D25, 0) | K25: =F25+G25-H25+I25-J25 | L25: =Moc_Luy_Ke_T8_Chot_So!D25+D25 | M25: =IF(L25>0, N25/L25, 0) | N25: =Moc_Luy_Ke_T8_Chot_So!F25+F25 | O25: =Moc_Luy_Ke_T8_Chot_So!G25+G25 | P25: =Moc_Luy_Ke_T8_Chot_So!H25+H25 | Q25: =Moc_Luy_Ke_T8_Chot_So!I25+I25-J25 | R25: =Moc_Luy_Ke_T8_Chot_So!J25+K25
A26: • | B26: Xuất khẩu | E26: =IF(D26>0, F26/D26, 0) | K26: =F26+G26-H26+I26-J26 | L26: =Moc_Luy_Ke_T8_Chot_So!D26+D26 | M26: =IF(L26>0, N26/L26, 0) | N26: =Moc_Luy_Ke_T8_Chot_So!F26+F26 | O26: =Moc_Luy_Ke_T8_Chot_So!G26+G26 | P26: =Moc_Luy_Ke_T8_Chot_So!H26+H26 | Q26: =Moc_Luy_Ke_T8_Chot_So!I26+I26-J26 | R26: =Moc_Luy_Ke_T8_Chot_So!J26+K26
A27: • | B27: Xuất bán trong nước | E27: =IF(D27>0, F27/D27, 0) | K27: =F27+G27-H27+I27-J27 | L27: =Moc_Luy_Ke_T8_Chot_So!D27+D27 | M27: =IF(L27>0, N27/L27, 0) | N27: =Moc_Luy_Ke_T8_Chot_So!F27+F27 | O27: =Moc_Luy_Ke_T8_Chot_So!G27+G27 | P27: =Moc_Luy_Ke_T8_Chot_So!H27+H27 | Q27: =Moc_Luy_Ke_T8_Chot_So!I27+I27-J27 | R27: =Moc_Luy_Ke_T8_Chot_So!J27+K27
A28: 4.2 | B28: HĐ đầu tư Tài chính | E28: =IF(D28>0, F28/D28, 0) | K28: =F28+G28-H28+I28-J28 | L28: =Moc_Luy_Ke_T8_Chot_So!D28+D28 | M28: =IF(L28>0, N28/L28, 0) | N28: =Moc_Luy_Ke_T8_Chot_So!F28+F28 | O28: =Moc_Luy_Ke_T8_Chot_So!G28+G28 | P28: =Moc_Luy_Ke_T8_Chot_So!H28+H28 | Q28: =Moc_Luy_Ke_T8_Chot_So!I28+I28-J28 | R28: =Moc_Luy_Ke_T8_Chot_So!J28+K28
A29: 5 | B29: XESCO (Xem Sơn) | C29: 15000 | E29: =IF(D29>0, F29/D29, 0) | K29: =F29+G29-H29+I29-J29 | L29: =Moc_Luy_Ke_T8_Chot_So!D29+D29 | M29: =IF(L29>0, N29/L29, 0) | N29: =Moc_Luy_Ke_T8_Chot_So!F29+F29 | O29: =Moc_Luy_Ke_T8_Chot_So!G29+G29 | P29: =Moc_Luy_Ke_T8_Chot_So!H29+H29 | Q29: =Moc_Luy_Ke_T8_Chot_So!I29+I29-J29 | R29: =Moc_Luy_Ke_T8_Chot_So!J29+K29
A30: 5.1 | B30: Xesco - KT | E30: =IF(D30>0, F30/D30, 0) | K30: =F30+G30-H30+I30-J30 | L30: =Moc_Luy_Ke_T8_Chot_So!D30+D30 | M30: =IF(L30>0, N30/L30, 0) | N30: =Moc_Luy_Ke_T8_Chot_So!F30+F30 | O30: =Moc_Luy_Ke_T8_Chot_So!G30+G30 | P30: =Moc_Luy_Ke_T8_Chot_So!H30+H30 | Q30: =Moc_Luy_Ke_T8_Chot_So!I30+I30-J30 | R30: =Moc_Luy_Ke_T8_Chot_So!J30+K30
A31: • | B31: Kỹ thuật thuê máy | E31: =IF(D31>0, F31/D31, 0) | K31: =F31+G31-H31+I31-J31 | L31: =Moc_Luy_Ke_T8_Chot_So!D31+D31 | M31: =IF(L31>0, N31/L31, 0) | N31: =Moc_Luy_Ke_T8_Chot_So!F31+F31 | O31: =Moc_Luy_Ke_T8_Chot_So!G31+G31 | P31: =Moc_Luy_Ke_T8_Chot_So!H31+H31 | Q31: =Moc_Luy_Ke_T8_Chot_So!I31+I31-J31 | R31: =Moc_Luy_Ke_T8_Chot_So!J31+K31
A32: • | B32: Metercharge | E32: =IF(D32>0, F32/D32, 0) | K32: =F32+G32-H32+I32-J32 | L32: =Moc_Luy_Ke_T8_Chot_So!D32+D32 | M32: =IF(L32>0, N32/L32, 0) | N32: =Moc_Luy_Ke_T8_Chot_So!F32+F32 | O32: =Moc_Luy_Ke_T8_Chot_So!G32+G32 | P32: =Moc_Luy_Ke_T8_Chot_So!H32+H32 | Q32: =Moc_Luy_Ke_T8_Chot_So!I32+I32-J32 | R32: =Moc_Luy_Ke_T8_Chot_So!J32+K32
A33: • | B33: Dịch vụ kỹ thuật | E33: =IF(D33>0, F33/D33, 0) | K33: =F33+G33-H33+I33-J33 | L33: =Moc_Luy_Ke_T8_Chot_So!D33+D33 | M33: =IF(L33>0, N33/L33, 0) | N33: =Moc_Luy_Ke_T8_Chot_So!F33+F33 | O33: =Moc_Luy_Ke_T8_Chot_So!G33+G33 | P33: =Moc_Luy_Ke_T8_Chot_So!H33+H33 | Q33: =Moc_Luy_Ke_T8_Chot_So!I33+I33-J33 | R33: =Moc_Luy_Ke_T8_Chot_So!J33+K33
A34: 5.2 | B34: Xesco - KD | E34: =IF(D34>0, F34/D34, 0) | K34: =F34+G34-H34+I34-J34 | L34: =Moc_Luy_Ke_T8_Chot_So!D34+D34 | M34: =IF(L34>0, N34/L34, 0) | N34: =Moc_Luy_Ke_T8_Chot_So!F34+F34 | O34: =Moc_Luy_Ke_T8_Chot_So!G34+G34 | P34: =Moc_Luy_Ke_T8_Chot_So!H34+H34 | Q34: =Moc_Luy_Ke_T8_Chot_So!I34+I34-J34 | R34: =Moc_Luy_Ke_T8_Chot_So!J34+K34
A35: • | B35: Bán máy lẻ | E35: =IF(D35>0, F35/D35, 0) | K35: =F35+G35-H35+I35-J35 | L35: =Moc_Luy_Ke_T8_Chot_So!D35+D35 | M35: =IF(L35>0, N35/L35, 0) | N35: =Moc_Luy_Ke_T8_Chot_So!F35+F35 | O35: =Moc_Luy_Ke_T8_Chot_So!G35+G35 | P35: =Moc_Luy_Ke_T8_Chot_So!H35+H35 | Q35: =Moc_Luy_Ke_T8_Chot_So!I35+I35-J35 | R35: =Moc_Luy_Ke_T8_Chot_So!J35+K35
A36: • | B36: Dự án Xesco | E36: =IF(D36>0, F36/D36, 0) | K36: =F36+G36-H36+I36-J36 | L36: =Moc_Luy_Ke_T8_Chot_So!D36+D36 | M36: =IF(L36>0, N36/L36, 0) | N36: =Moc_Luy_Ke_T8_Chot_So!F36+F36 | O36: =Moc_Luy_Ke_T8_Chot_So!G36+G36 | P36: =Moc_Luy_Ke_T8_Chot_So!H36+H36 | Q36: =Moc_Luy_Ke_T8_Chot_So!I36+I36-J36 | R36: =Moc_Luy_Ke_T8_Chot_So!J36+K36
A37: • | B37: KD sỉ | E37: =IF(D37>0, F37/D37, 0) | K37: =F37+G37-H37+I37-J37 | L37: =Moc_Luy_Ke_T8_Chot_So!D37+D37 | M37: =IF(L37>0, N37/L37, 0) | N37: =Moc_Luy_Ke_T8_Chot_So!F37+F37 | O37: =Moc_Luy_Ke_T8_Chot_So!G37+G37 | P37: =Moc_Luy_Ke_T8_Chot_So!H37+H37 | Q37: =Moc_Luy_Ke_T8_Chot_So!I37+I37-J37 | R37: =Moc_Luy_Ke_T8_Chot_So!J37+K37
A38: • | B38: KD Online | E38: =IF(D38>0, F38/D38, 0) | K38: =F38+G38-H38+I38-J38 | L38: =Moc_Luy_Ke_T8_Chot_So!D38+D38 | M38: =IF(L38>0, N38/L38, 0) | N38: =Moc_Luy_Ke_T8_Chot_So!F38+F38 | O38: =Moc_Luy_Ke_T8_Chot_So!G38+G38 | P38: =Moc_Luy_Ke_T8_Chot_So!H38+H38 | Q38: =Moc_Luy_Ke_T8_Chot_So!I38+I38-J38 | R38: =Moc_Luy_Ke_T8_Chot_So!J38+K38
A39: • | B39: KD Thuê máy | E39: =IF(D39>0, F39/D39, 0) | K39: =F39+G39-H39+I39-J39 | L39: =Moc_Luy_Ke_T8_Chot_So!D39+D39 | M39: =IF(L39>0, N39/L39, 0) | N39: =Moc_Luy_Ke_T8_Chot_So!F39+F39 | O39: =Moc_Luy_Ke_T8_Chot_So!G39+G39 | P39: =Moc_Luy_Ke_T8_Chot_So!H39+H39 | Q39: =Moc_Luy_Ke_T8_Chot_So!I39+I39-J39 | R39: =Moc_Luy_Ke_T8_Chot_So!J39+K39
A40: • | B40: Nội bộ (Công ty) | E40: =IF(D40>0, F40/D40, 0) | K40: =F40+G40-H40+I40-J40 | L40: =Moc_Luy_Ke_T8_Chot_So!D40+D40 | M40: =IF(L40>0, N40/L40, 0) | N40: =Moc_Luy_Ke_T8_Chot_So!F40+F40 | O40: =Moc_Luy_Ke_T8_Chot_So!G40+G40 | P40: =Moc_Luy_Ke_T8_Chot_So!H40+H40 | Q40: =Moc_Luy_Ke_T8_Chot_So!I40+I40-J40 | R40: =Moc_Luy_Ke_T8_Chot_So!J40+K40
...

Sheet Thang_10
A1: BÁO CÁO KẾT QUẢ HOẠT ĐỘNG KINH DOANH - THÁNG 10/2026
A2: Đơn vị tính: Triệu đồng (Tr.đ) | Tự động cộng dồn lũy kế kế thừa Tháng 09 | Đồng bộ trực tiếp Dashboard VPS Group
A3: TT | B3: NỘI DUNG / ĐƠN VỊ KINH DOANH | C3: VỐN ĐT | D3: PHÁT SINH THÁNG 10/2026 | L3: LŨY KẾ ĐẾN HẾT THÁNG 10/2026
D4: DS | E4: % LG | F4: LG | G4: HT LG | H4: CHI PHÍ | I4: TN KHÁC | J4: CP KHÁC | K4: LNTT | L4: DS | M4: % LG | N4: LG | O4: HT LG | P4: CHI PHÍ | Q4: TN KHÁC | R4: LNTT
A5: I | B5: MIỀN BẮC | C5: 90000 | E5: =IF(D5>0, F5/D5, 0) | K5: =F5+G5-H5+I5-J5 | L5: ='Thang_09'!L5+D5 | M5: =IF(L5>0, N5/L5, 0) | N5: ='Thang_09'!N5+F5 | O5: ='Thang_09'!O5+G5 | P5: ='Thang_09'!P5+H5 | Q5: ='Thang_09'!Q5+I5-J5 | R5: ='Thang_09'!R5+K5
A6: 1 | B6: THH (Tân Hồng Hà) | C6: 50000 | E6: =IF(D6>0, F6/D6, 0) | K6: =F6+G6-H6+I6-J6 | L6: ='Thang_09'!L6+D6 | M6: =IF(L6>0, N6/L6, 0) | N6: ='Thang_09'!N6+F6 | O6: ='Thang_09'!O6+G6 | P6: ='Thang_09'!P6+H6 | Q6: ='Thang_09'!Q6+I6-J6 | R6: ='Thang_09'!R6+K6
A7: a | B7: Khối dịch vụ kỹ thuật | E7: =IF(D7>0, F7/D7, 0) | K7: =F7+G7-H7+I7-J7 | L7: ='Thang_09'!L7+D7 | M7: =IF(L7>0, N7/L7, 0) | N7: ='Thang_09'!N7+F7 | O7: ='Thang_09'!O7+G7 | P7: ='Thang_09'!P7+H7 | Q7: ='Thang_09'!Q7+I7-J7 | R7: ='Thang_09'!R7+K7
A8: a.1 | B8: Tổ Dịch vụ | E8: =IF(D8>0, F8/D8, 0) | K8: =F8+G8-H8+I8-J8 | L8: ='Thang_09'!L8+D8 | M8: =IF(L8>0, N8/L8, 0) | N8: ='Thang_09'!N8+F8 | O8: ='Thang_09'!O8+G8 | P8: ='Thang_09'!P8+H8 | Q8: ='Thang_09'!Q8+I8-J8 | R8: ='Thang_09'!R8+K8
A9: a.2 | B9: Tổ mực in | E9: =IF(D9>0, F9/D9, 0) | K9: =F9+G9-H9+I9-J9 | L9: ='Thang_09'!L9+D9 | M9: =IF(L9>0, N9/L9, 0) | N9: ='Thang_09'!N9+F9 | O9: ='Thang_09'!O9+G9 | P9: ='Thang_09'!P9+H9 | Q9: ='Thang_09'!Q9+I9-J9 | R9: ='Thang_09'!R9+K9
A10: a.3 | B10: Thuê máy | E10: =IF(D10>0, F10/D10, 0) | K10: =F10+G10-H10+I10-J10 | L10: ='Thang_09'!L10+D10 | M10: =IF(L10>0, N10/L10, 0) | N10: ='Thang_09'!N10+F10 | O10: ='Thang_09'!O10+G10 | P10: ='Thang_09'!P10+H10 | Q10: ='Thang_09'!Q10+I10-J10 | R10: ='Thang_09'!R10+K10
A11: a.4 | B11: Metercharge | E11: =IF(D11>0, F11/D11, 0) | K11: =F11+G11-H11+I11-J11 | L11: ='Thang_09'!L11+D11 | M11: =IF(L11>0, N11/L11, 0) | N11: ='Thang_09'!N11+F11 | O11: ='Thang_09'!O11+G11 | P11: ='Thang_09'!P11+H11 | Q11: ='Thang_09'!Q11+I11-J11 | R11: ='Thang_09'!R11+K11
A12: a.5 | B12: Kinh doanh Online | E12: =IF(D12>0, F12/D12, 0) | K12: =F12+G12-H12+I12-J12 | L12: ='Thang_09'!L12+D12 | M12: =IF(L12>0, N12/L12, 0) | N12: ='Thang_09'!N12+F12 | O12: ='Thang_09'!O12+G12 | P12: ='Thang_09'!P12+H12 | Q12: ='Thang_09'!Q12+I12-J12 | R12: ='Thang_09'!R12+K12
A13: b | B13: Kinh doanh tổng hợp | E13: =IF(D13>0, F13/D13, 0) | K13: =F13+G13-H13+I13-J13 | L13: ='Thang_09'!L13+D13 | M13: =IF(L13>0, N13/L13, 0) | N13: ='Thang_09'!N13+F13 | O13: ='Thang_09'!O13+G13 | P13: ='Thang_09'!P13+H13 | Q13: ='Thang_09'!Q13+I13-J13 | R13: ='Thang_09'!R13+K13
A14: c | B14: Kinh doanh bán buôn | E14: =IF(D14>0, F14/D14, 0) | K14: =F14+G14-H14+I14-J14 | L14: ='Thang_09'!L14+D14 | M14: =IF(L14>0, N14/L14, 0) | N14: ='Thang_09'!N14+F14 | O14: ='Thang_09'!O14+G14 | P14: ='Thang_09'!P14+H14 | Q14: ='Thang_09'!Q14+I14-J14 | R14: ='Thang_09'!R14+K14
A15: d | B15: Dự án | E15: =IF(D15>0, F15/D15, 0) | K15: =F15+G15-H15+I15-J15 | L15: ='Thang_09'!L15+D15 | M15: =IF(L15>0, N15/L15, 0) | N15: ='Thang_09'!N15+F15 | O15: ='Thang_09'!O15+G15 | P15: ='Thang_09'!P15+H15 | Q15: ='Thang_09'!Q15+I15-J15 | R15: ='Thang_09'!R15+K15
A16: 2 | B16: Việt | C16: 10000 | E16: =IF(D16>0, F16/D16, 0) | K16: =F16+G16-H16+I16-J16 | L16: ='Thang_09'!L16+D16 | M16: =IF(L16>0, N16/L16, 0) | N16: ='Thang_09'!N16+F16 | O16: ='Thang_09'!O16+G16 | P16: ='Thang_09'!P16+H16 | Q16: ='Thang_09'!Q16+I16-J16 | R16: ='Thang_09'!R16+K16
A17: 2.1 | B17: Thuê máy | E17: =IF(D17>0, F17/D17, 0) | K17: =F17+G17-H17+I17-J17 | L17: ='Thang_09'!L17+D17 | M17: =IF(L17>0, N17/L17, 0) | N17: ='Thang_09'!N17+F17 | O17: ='Thang_09'!O17+G17 | P17: ='Thang_09'!P17+H17 | Q17: ='Thang_09'!Q17+I17-J17 | R17: ='Thang_09'!R17+K17
A18: 2.2 | B18: KDTH | E18: =IF(D18>0, F18/D18, 0) | K18: =F18+G18-H18+I18-J18 | L18: ='Thang_09'!L18+D18 | M18: =IF(L18>0, N18/L18, 0) | N18: ='Thang_09'!N18+F18 | O18: ='Thang_09'!O18+G18 | P18: ='Thang_09'!P18+H18 | Q18: ='Thang_09'!Q18+I18-J18 | R18: ='Thang_09'!R18+K18
A19: 2.3 | B19: KD online | E19: =IF(D19>0, F19/D19, 0) | K19: =F19+G19-H19+I19-J19 | L19: ='Thang_09'!L19+D19 | M19: =IF(L19>0, N19/L19, 0) | N19: ='Thang_09'!N19+F19 | O19: ='Thang_09'!O19+G19 | P19: ='Thang_09'!P19+H19 | Q19: ='Thang_09'!Q19+I19-J19 | R19: ='Thang_09'!R19+K19
A20: 2.4 | B20: Cửa hàng | E20: =IF(D20>0, F20/D20, 0) | K20: =F20+G20-H20+I20-J20 | L20: ='Thang_09'!L20+D20 | M20: =IF(L20>0, N20/L20, 0) | N20: ='Thang_09'!N20+F20 | O20: ='Thang_09'!O20+G20 | P20: ='Thang_09'!P20+H20 | Q20: ='Thang_09'!Q20+I20-J20 | R20: ='Thang_09'!R20+K20
A21: 2.5 | B21: Nội bộ | E21: =IF(D21>0, F21/D21, 0) | K21: =F21+G21-H21+I21-J21 | L21: ='Thang_09'!L21+D21 | M21: =IF(L21>0, N21/L21, 0) | N21: ='Thang_09'!N21+F21 | O21: ='Thang_09'!O21+G21 | P21: ='Thang_09'!P21+H21 | Q21: ='Thang_09'!Q21+I21-J21 | R21: ='Thang_09'!R21+K21
A22: 3 | B22: ITSS | C22: 5000 | E22: =IF(D22>0, F22/D22, 0) | K22: =F22+G22-H22+I22-J22 | L22: ='Thang_09'!L22+D22 | M22: =IF(L22>0, N22/L22, 0) | N22: ='Thang_09'!N22+F22 | O22: ='Thang_09'!O22+G22 | P22: ='Thang_09'!P22+H22 | Q22: ='Thang_09'!Q22+I22-J22 | R22: ='Thang_09'!R22+K22
A23: 4 | B23: CTY VPS | C23: 10000 | E23: =IF(D23>0, F23/D23, 0) | K23: =F23+G23-H23+I23-J23 | L23: ='Thang_09'!L23+D23 | M23: =IF(L23>0, N23/L23, 0) | N23: ='Thang_09'!N23+F23 | O23: ='Thang_09'!O23+G23 | P23: ='Thang_09'!P23+H23 | Q23: ='Thang_09'!Q23+I23-J23 | R23: ='Thang_09'!R23+K23
A24: 4.1 | B24: VP VPS - hoạt động KD | E24: =IF(D24>0, F24/D24, 0) | K24: =F24+G24-H24+I24-J24 | L24: ='Thang_09'!L24+D24 | M24: =IF(L24>0, N24/L24, 0) | N24: ='Thang_09'!N24+F24 | O24: ='Thang_09'!O24+G24 | P24: ='Thang_09'!P24+H24 | Q24: ='Thang_09'!Q24+I24-J24 | R24: ='Thang_09'!R24+K24
A25: • | B25: VPS bán nội bộ | E25: =IF(D25>0, F25/D25, 0) | K25: =F25+G25-H25+I25-J25 | L25: ='Thang_09'!L25+D25 | M25: =IF(L25>0, N25/L25, 0) | N25: ='Thang_09'!N25+F25 | O25: ='Thang_09'!O25+G25 | P25: ='Thang_09'!P25+H25 | Q25: ='Thang_09'!Q25+I25-J25 | R25: ='Thang_09'!R25+K25
A26: • | B26: Xuất khẩu | E26: =IF(D26>0, F26/D26, 0) | K26: =F26+G26-H26+I26-J26 | L26: ='Thang_09'!L26+D26 | M26: =IF(L26>0, N26/L26, 0) | N26: ='Thang_09'!N26+F26 | O26: ='Thang_09'!O26+G26 | P26: ='Thang_09'!P26+H26 | Q26: ='Thang_09'!Q26+I26-J26 | R26: ='Thang_09'!R26+K26
A27: • | B27: Xuất bán trong nước | E27: =IF(D27>0, F27/D27, 0) | K27: =F27+G27-H27+I27-J27 | L27: ='Thang_09'!L27+D27 | M27: =IF(L27>0, N27/L27, 0) | N27: ='Thang_09'!N27+F27 | O27: ='Thang_09'!O27+G27 | P27: ='Thang_09'!P27+H27 | Q27: ='Thang_09'!Q27+I27-J27 | R27: ='Thang_09'!R27+K27
A28: 4.2 | B28: HĐ đầu tư Tài chính | E28: =IF(D28>0, F28/D28, 0) | K28: =F28+G28-H28+I28-J28 | L28: ='Thang_09'!L28+D28 | M28: =IF(L28>0, N28/L28, 0) | N28: ='Thang_09'!N28+F28 | O28: ='Thang_09'!O28+G28 | P28: ='Thang_09'!P28+H28 | Q28: ='Thang_09'!Q28+I28-J28 | R28: ='Thang_09'!R28+K28
A29: 5 | B29: XESCO (Xem Sơn) | C29: 15000 | E29: =IF(D29>0, F29/D29, 0) | K29: =F29+G29-H29+I29-J29 | L29: ='Thang_09'!L29+D29 | M29: =IF(L29>0, N29/L29, 0) | N29: ='Thang_09'!N29+F29 | O29: ='Thang_09'!O29+G29 | P29: ='Thang_09'!P29+H29 | Q29: ='Thang_09'!Q29+I29-J29 | R29: ='Thang_09'!R29+K29
A30: 5.1 | B30: Xesco - KT | E30: =IF(D30>0, F30/D30, 0) | K30: =F30+G30-H30+I30-J30 | L30: ='Thang_09'!L30+D30 | M30: =IF(L30>0, N30/L30, 0) | N30: ='Thang_09'!N30+F30 | O30: ='Thang_09'!O30+G30 | P30: ='Thang_09'!P30+H30 | Q30: ='Thang_09'!Q30+I30-J30 | R30: ='Thang_09'!R30+K30
A31: • | B31: Kỹ thuật thuê máy | E31: =IF(D31>0, F31/D31, 0) | K31: =F31+G31-H31+I31-J31 | L31: ='Thang_09'!L31+D31 | M31: =IF(L31>0, N31/L31, 0) | N31: ='Thang_09'!N31+F31 | O31: ='Thang_09'!O31+G31 | P31: ='Thang_09'!P31+H31 | Q31: ='Thang_09'!Q31+I31-J31 | R31: ='Thang_09'!R31+K31
A32: • | B32: Metercharge | E32: =IF(D32>0, F32/D32, 0) | K32: =F32+G32-H32+I32-J32 | L32: ='Thang_09'!L32+D32 | M32: =IF(L32>0, N32/L32, 0) | N32: ='Thang_09'!N32+F32 | O32: ='Thang_09'!O32+G32 | P32: ='Thang_09'!P32+H32 | Q32: ='Thang_09'!Q32+I32-J32 | R32: ='Thang_09'!R32+K32
A33: • | B33: Dịch vụ kỹ thuật | E33: =IF(D33>0, F33/D33, 0) | K33: =F33+G33-H33+I33-J33 | L33: ='Thang_09'!L33+D33 | M33: =IF(L33>0, N33/L33, 0) | N33: ='Thang_09'!N33+F33 | O33: ='Thang_09'!O33+G33 | P33: ='Thang_09'!P33+H33 | Q33: ='Thang_09'!Q33+I33-J33 | R33: ='Thang_09'!R33+K33
A34: 5.2 | B34: Xesco - KD | E34: =IF(D34>0, F34/D34, 0) | K34: =F34+G34-H34+I34-J34 | L34: ='Thang_09'!L34+D34 | M34: =IF(L34>0, N34/L34, 0) | N34: ='Thang_09'!N34+F34 | O34: ='Thang_09'!O34+G34 | P34: ='Thang_09'!P34+H34 | Q34: ='Thang_09'!Q34+I34-J34 | R34: ='Thang_09'!R34+K34
A35: • | B35: Bán máy lẻ | E35: =IF(D35>0, F35/D35, 0) | K35: =F35+G35-H35+I35-J35 | L35: ='Thang_09'!L35+D35 | M35: =IF(L35>0, N35/L35, 0) | N35: ='Thang_09'!N35+F35 | O35: ='Thang_09'!O35+G35 | P35: ='Thang_09'!P35+H35 | Q35: ='Thang_09'!Q35+I35-J35 | R35: ='Thang_09'!R35+K35
A36: • | B36: Dự án Xesco | E36: =IF(D36>0, F36/D36, 0) | K36: =F36+G36-H36+I36-J36 | L36: ='Thang_09'!L36+D36 | M36: =IF(L36>0, N36/L36, 0) | N36: ='Thang_09'!N36+F36 | O36: ='Thang_09'!O36+G36 | P36: ='Thang_09'!P36+H36 | Q36: ='Thang_09'!Q36+I36-J36 | R36: ='Thang_09'!R36+K36
A37: • | B37: KD sỉ | E37: =IF(D37>0, F37/D37, 0) | K37: =F37+G37-H37+I37-J37 | L37: ='Thang_09'!L37+D37 | M37: =IF(L37>0, N37/L37, 0) | N37: ='Thang_09'!N37+F37 | O37: ='Thang_09'!O37+G37 | P37: ='Thang_09'!P37+H37 | Q37: ='Thang_09'!Q37+I37-J37 | R37: ='Thang_09'!R37+K37
A38: • | B38: KD Online | E38: =IF(D38>0, F38/D38, 0) | K38: =F38+G38-H38+I38-J38 | L38: ='Thang_09'!L38+D38 | M38: =IF(L38>0, N38/L38, 0) | N38: ='Thang_09'!N38+F38 | O38: ='Thang_09'!O38+G38 | P38: ='Thang_09'!P38+H38 | Q38: ='Thang_09'!Q38+I38-J38 | R38: ='Thang_09'!R38+K38
A39: • | B39: KD Thuê máy | E39: =IF(D39>0, F39/D39, 0) | K39: =F39+G39-H39+I39-J39 | L39: ='Thang_09'!L39+D39 | M39: =IF(L39>0, N39/L39, 0) | N39: ='Thang_09'!N39+F39 | O39: ='Thang_09'!O39+G39 | P39: ='Thang_09'!P39+H39 | Q39: ='Thang_09'!Q39+I39-J39 | R39: ='Thang_09'!R39+K39
A40: • | B40: Nội bộ (Công ty) | E40: =IF(D40>0, F40/D40, 0) | K40: =F40+G40-H40+I40-J40 | L40: ='Thang_09'!L40+D40 | M40: =IF(L40>0, N40/L40, 0) | N40: ='Thang_09'!N40+F40 | O40: ='Thang_09'!O40+G40 | P40: ='Thang_09'!P40+H40 | Q40: ='Thang_09'!Q40+I40-J40 | R40: ='Thang_09'!R40+K40
...

Sheet Thang_11
A1: BÁO CÁO KẾT QUẢ HOẠT ĐỘNG KINH DOANH - THÁNG 11/2026
A2: Đơn vị tính: Triệu đồng (Tr.đ) | Tự động cộng dồn lũy kế kế thừa Tháng 10 | Đồng bộ trực tiếp Dashboard VPS Group
A3: TT | B3: NỘI DUNG / ĐƠN VỊ KINH DOANH | C3: VỐN ĐT | D3: PHÁT SINH THÁNG 11/2026 | L3: LŨY KẾ ĐẾN HẾT THÁNG 11/2026
D4: DS | E4: % LG | F4: LG | G4: HT LG | H4: CHI PHÍ | I4: TN KHÁC | J4: CP KHÁC | K4: LNTT | L4: DS | M4: % LG | N4: LG | O4: HT LG | P4: CHI PHÍ | Q4: TN KHÁC | R4: LNTT
A5: I | B5: MIỀN BẮC | C5: 90000 | E5: =IF(D5>0, F5/D5, 0) | K5: =F5+G5-H5+I5-J5 | L5: ='Thang_10'!L5+D5 | M5: =IF(L5>0, N5/L5, 0) | N5: ='Thang_10'!N5+F5 | O5: ='Thang_10'!O5+G5 | P5: ='Thang_10'!P5+H5 | Q5: ='Thang_10'!Q5+I5-J5 | R5: ='Thang_10'!R5+K5
A6: 1 | B6: THH (Tân Hồng Hà) | C6: 50000 | E6: =IF(D6>0, F6/D6, 0) | K6: =F6+G6-H6+I6-J6 | L6: ='Thang_10'!L6+D6 | M6: =IF(L6>0, N6/L6, 0) | N6: ='Thang_10'!N6+F6 | O6: ='Thang_10'!O6+G6 | P6: ='Thang_10'!P6+H6 | Q6: ='Thang_10'!Q6+I6-J6 | R6: ='Thang_10'!R6+K6
A7: a | B7: Khối dịch vụ kỹ thuật | E7: =IF(D7>0, F7/D7, 0) | K7: =F7+G7-H7+I7-J7 | L7: ='Thang_10'!L7+D7 | M7: =IF(L7>0, N7/L7, 0) | N7: ='Thang_10'!N7+F7 | O7: ='Thang_10'!O7+G7 | P7: ='Thang_10'!P7+H7 | Q7: ='Thang_10'!Q7+I7-J7 | R7: ='Thang_10'!R7+K7
A8: a.1 | B8: Tổ Dịch vụ | E8: =IF(D8>0, F8/D8, 0) | K8: =F8+G8-H8+I8-J8 | L8: ='Thang_10'!L8+D8 | M8: =IF(L8>0, N8/L8, 0) | N8: ='Thang_10'!N8+F8 | O8: ='Thang_10'!O8+G8 | P8: ='Thang_10'!P8+H8 | Q8: ='Thang_10'!Q8+I8-J8 | R8: ='Thang_10'!R8+K8
A9: a.2 | B9: Tổ mực in | E9: =IF(D9>0, F9/D9, 0) | K9: =F9+G9-H9+I9-J9 | L9: ='Thang_10'!L9+D9 | M9: =IF(L9>0, N9/L9, 0) | N9: ='Thang_10'!N9+F9 | O9: ='Thang_10'!O9+G9 | P9: ='Thang_10'!P9+H9 | Q9: ='Thang_10'!Q9+I9-J9 | R9: ='Thang_10'!R9+K9
A10: a.3 | B10: Thuê máy | E10: =IF(D10>0, F10/D10, 0) | K10: =F10+G10-H10+I10-J10 | L10: ='Thang_10'!L10+D10 | M10: =IF(L10>0, N10/L10, 0) | N10: ='Thang_10'!N10+F10 | O10: ='Thang_10'!O10+G10 | P10: ='Thang_10'!P10+H10 | Q10: ='Thang_10'!Q10+I10-J10 | R10: ='Thang_10'!R10+K10
A11: a.4 | B11: Metercharge | E11: =IF(D11>0, F11/D11, 0) | K11: =F11+G11-H11+I11-J11 | L11: ='Thang_10'!L11+D11 | M11: =IF(L11>0, N11/L11, 0) | N11: ='Thang_10'!N11+F11 | O11: ='Thang_10'!O11+G11 | P11: ='Thang_10'!P11+H11 | Q11: ='Thang_10'!Q11+I11-J11 | R11: ='Thang_10'!R11+K11
A12: a.5 | B12: Kinh doanh Online | E12: =IF(D12>0, F12/D12, 0) | K12: =F12+G12-H12+I12-J12 | L12: ='Thang_10'!L12+D12 | M12: =IF(L12>0, N12/L12, 0) | N12: ='Thang_10'!N12+F12 | O12: ='Thang_10'!O12+G12 | P12: ='Thang_10'!P12+H12 | Q12: ='Thang_10'!Q12+I12-J12 | R12: ='Thang_10'!R12+K12
A13: b | B13: Kinh doanh tổng hợp | E13: =IF(D13>0, F13/D13, 0) | K13: =F13+G13-H13+I13-J13 | L13: ='Thang_10'!L13+D13 | M13: =IF(L13>0, N13/L13, 0) | N13: ='Thang_10'!N13+F13 | O13: ='Thang_10'!O13+G13 | P13: ='Thang_10'!P13+H13 | Q13: ='Thang_10'!Q13+I13-J13 | R13: ='Thang_10'!R13+K13
A14: c | B14: Kinh doanh bán buôn | E14: =IF(D14>0, F14/D14, 0) | K14: =F14+G14-H14+I14-J14 | L14: ='Thang_10'!L14+D14 | M14: =IF(L14>0, N14/L14, 0) | N14: ='Thang_10'!N14+F14 | O14: ='Thang_10'!O14+G14 | P14: ='Thang_10'!P14+H14 | Q14: ='Thang_10'!Q14+I14-J14 | R14: ='Thang_10'!R14+K14
A15: d | B15: Dự án | E15: =IF(D15>0, F15/D15, 0) | K15: =F15+G15-H15+I15-J15 | L15: ='Thang_10'!L15+D15 | M15: =IF(L15>0, N15/L15, 0) | N15: ='Thang_10'!N15+F15 | O15: ='Thang_10'!O15+G15 | P15: ='Thang_10'!P15+H15 | Q15: ='Thang_10'!Q15+I15-J15 | R15: ='Thang_10'!R15+K15
A16: 2 | B16: Việt | C16: 10000 | E16: =IF(D16>0, F16/D16, 0) | K16: =F16+G16-H16+I16-J16 | L16: ='Thang_10'!L16+D16 | M16: =IF(L16>0, N16/L16, 0) | N16: ='Thang_10'!N16+F16 | O16: ='Thang_10'!O16+G16 | P16: ='Thang_10'!P16+H16 | Q16: ='Thang_10'!Q16+I16-J16 | R16: ='Thang_10'!R16+K16
A17: 2.1 | B17: Thuê máy | E17: =IF(D17>0, F17/D17, 0) | K17: =F17+G17-H17+I17-J17 | L17: ='Thang_10'!L17+D17 | M17: =IF(L17>0, N17/L17, 0) | N17: ='Thang_10'!N17+F17 | O17: ='Thang_10'!O17+G17 | P17: ='Thang_10'!P17+H17 | Q17: ='Thang_10'!Q17+I17-J17 | R17: ='Thang_10'!R17+K17
A18: 2.2 | B18: KDTH | E18: =IF(D18>0, F18/D18, 0) | K18: =F18+G18-H18+I18-J18 | L18: ='Thang_10'!L18+D18 | M18: =IF(L18>0, N18/L18, 0) | N18: ='Thang_10'!N18+F18 | O18: ='Thang_10'!O18+G18 | P18: ='Thang_10'!P18+H18 | Q18: ='Thang_10'!Q18+I18-J18 | R18: ='Thang_10'!R18+K18
A19: 2.3 | B19: KD online | E19: =IF(D19>0, F19/D19, 0) | K19: =F19+G19-H19+I19-J19 | L19: ='Thang_10'!L19+D19 | M19: =IF(L19>0, N19/L19, 0) | N19: ='Thang_10'!N19+F19 | O19: ='Thang_10'!O19+G19 | P19: ='Thang_10'!P19+H19 | Q19: ='Thang_10'!Q19+I19-J19 | R19: ='Thang_10'!R19+K19
A20: 2.4 | B20: Cửa hàng | E20: =IF(D20>0, F20/D20, 0) | K20: =F20+G20-H20+I20-J20 | L20: ='Thang_10'!L20+D20 | M20: =IF(L20>0, N20/L20, 0) | N20: ='Thang_10'!N20+F20 | O20: ='Thang_10'!O20+G20 | P20: ='Thang_10'!P20+H20 | Q20: ='Thang_10'!Q20+I20-J20 | R20: ='Thang_10'!R20+K20
A21: 2.5 | B21: Nội bộ | E21: =IF(D21>0, F21/D21, 0) | K21: =F21+G21-H21+I21-J21 | L21: ='Thang_10'!L21+D21 | M21: =IF(L21>0, N21/L21, 0) | N21: ='Thang_10'!N21+F21 | O21: ='Thang_10'!O21+G21 | P21: ='Thang_10'!P21+H21 | Q21: ='Thang_10'!Q21+I21-J21 | R21: ='Thang_10'!R21+K21
A22: 3 | B22: ITSS | C22: 5000 | E22: =IF(D22>0, F22/D22, 0) | K22: =F22+G22-H22+I22-J22 | L22: ='Thang_10'!L22+D22 | M22: =IF(L22>0, N22/L22, 0) | N22: ='Thang_10'!N22+F22 | O22: ='Thang_10'!O22+G22 | P22: ='Thang_10'!P22+H22 | Q22: ='Thang_10'!Q22+I22-J22 | R22: ='Thang_10'!R22+K22
A23: 4 | B23: CTY VPS | C23: 10000 | E23: =IF(D23>0, F23/D23, 0) | K23: =F23+G23-H23+I23-J23 | L23: ='Thang_10'!L23+D23 | M23: =IF(L23>0, N23/L23, 0) | N23: ='Thang_10'!N23+F23 | O23: ='Thang_10'!O23+G23 | P23: ='Thang_10'!P23+H23 | Q23: ='Thang_10'!Q23+I23-J23 | R23: ='Thang_10'!R23+K23
A24: 4.1 | B24: VP VPS - hoạt động KD | E24: =IF(D24>0, F24/D24, 0) | K24: =F24+G24-H24+I24-J24 | L24: ='Thang_10'!L24+D24 | M24: =IF(L24>0, N24/L24, 0) | N24: ='Thang_10'!N24+F24 | O24: ='Thang_10'!O24+G24 | P24: ='Thang_10'!P24+H24 | Q24: ='Thang_10'!Q24+I24-J24 | R24: ='Thang_10'!R24+K24
A25: • | B25: VPS bán nội bộ | E25: =IF(D25>0, F25/D25, 0) | K25: =F25+G25-H25+I25-J25 | L25: ='Thang_10'!L25+D25 | M25: =IF(L25>0, N25/L25, 0) | N25: ='Thang_10'!N25+F25 | O25: ='Thang_10'!O25+G25 | P25: ='Thang_10'!P25+H25 | Q25: ='Thang_10'!Q25+I25-J25 | R25: ='Thang_10'!R25+K25
A26: • | B26: Xuất khẩu | E26: =IF(D26>0, F26/D26, 0) | K26: =F26+G26-H26+I26-J26 | L26: ='Thang_10'!L26+D26 | M26: =IF(L26>0, N26/L26, 0) | N26: ='Thang_10'!N26+F26 | O26: ='Thang_10'!O26+G26 | P26: ='Thang_10'!P26+H26 | Q26: ='Thang_10'!Q26+I26-J26 | R26: ='Thang_10'!R26+K26
A27: • | B27: Xuất bán trong nước | E27: =IF(D27>0, F27/D27, 0) | K27: =F27+G27-H27+I27-J27 | L27: ='Thang_10'!L27+D27 | M27: =IF(L27>0, N27/L27, 0) | N27: ='Thang_10'!N27+F27 | O27: ='Thang_10'!O27+G27 | P27: ='Thang_10'!P27+H27 | Q27: ='Thang_10'!Q27+I27-J27 | R27: ='Thang_10'!R27+K27
A28: 4.2 | B28: HĐ đầu tư Tài chính | E28: =IF(D28>0, F28/D28, 0) | K28: =F28+G28-H28+I28-J28 | L28: ='Thang_10'!L28+D28 | M28: =IF(L28>0, N28/L28, 0) | N28: ='Thang_10'!N28+F28 | O28: ='Thang_10'!O28+G28 | P28: ='Thang_10'!P28+H28 | Q28: ='Thang_10'!Q28+I28-J28 | R28: ='Thang_10'!R28+K28
A29: 5 | B29: XESCO (Xem Sơn) | C29: 15000 | E29: =IF(D29>0, F29/D29, 0) | K29: =F29+G29-H29+I29-J29 | L29: ='Thang_10'!L29+D29 | M29: =IF(L29>0, N29/L29, 0) | N29: ='Thang_10'!N29+F29 | O29: ='Thang_10'!O29+G29 | P29: ='Thang_10'!P29+H29 | Q29: ='Thang_10'!Q29+I29-J29 | R29: ='Thang_10'!R29+K29
A30: 5.1 | B30: Xesco - KT | E30: =IF(D30>0, F30/D30, 0) | K30: =F30+G30-H30+I30-J30 | L30: ='Thang_10'!L30+D30 | M30: =IF(L30>0, N30/L30, 0) | N30: ='Thang_10'!N30+F30 | O30: ='Thang_10'!O30+G30 | P30: ='Thang_10'!P30+H30 | Q30: ='Thang_10'!Q30+I30-J30 | R30: ='Thang_10'!R30+K30
A31: • | B31: Kỹ thuật thuê máy | E31: =IF(D31>0, F31/D31, 0) | K31: =F31+G31-H31+I31-J31 | L31: ='Thang_10'!L31+D31 | M31: =IF(L31>0, N31/L31, 0) | N31: ='Thang_10'!N31+F31 | O31: ='Thang_10'!O31+G31 | P31: ='Thang_10'!P31+H31 | Q31: ='Thang_10'!Q31+I31-J31 | R31: ='Thang_10'!R31+K31
A32: • | B32: Metercharge | E32: =IF(D32>0, F32/D32, 0) | K32: =F32+G32-H32+I32-J32 | L32: ='Thang_10'!L32+D32 | M32: =IF(L32>0, N32/L32, 0) | N32: ='Thang_10'!N32+F32 | O32: ='Thang_10'!O32+G32 | P32: ='Thang_10'!P32+H32 | Q32: ='Thang_10'!Q32+I32-J32 | R32: ='Thang_10'!R32+K32
A33: • | B33: Dịch vụ kỹ thuật | E33: =IF(D33>0, F33/D33, 0) | K33: =F33+G33-H33+I33-J33 | L33: ='Thang_10'!L33+D33 | M33: =IF(L33>0, N33/L33, 0) | N33: ='Thang_10'!N33+F33 | O33: ='Thang_10'!O33+G33 | P33: ='Thang_10'!P33+H33 | Q33: ='Thang_10'!Q33+I33-J33 | R33: ='Thang_10'!R33+K33
A34: 5.2 | B34: Xesco - KD | E34: =IF(D34>0, F34/D34, 0) | K34: =F34+G34-H34+I34-J34 | L34: ='Thang_10'!L34+D34 | M34: =IF(L34>0, N34/L34, 0) | N34: ='Thang_10'!N34+F34 | O34: ='Thang_10'!O34+G34 | P34: ='Thang_10'!P34+H34 | Q34: ='Thang_10'!Q34+I34-J34 | R34: ='Thang_10'!R34+K34
A35: • | B35: Bán máy lẻ | E35: =IF(D35>0, F35/D35, 0) | K35: =F35+G35-H35+I35-J35 | L35: ='Thang_10'!L35+D35 | M35: =IF(L35>0, N35/L35, 0) | N35: ='Thang_10'!N35+F35 | O35: ='Thang_10'!O35+G35 | P35: ='Thang_10'!P35+H35 | Q35: ='Thang_10'!Q35+I35-J35 | R35: ='Thang_10'!R35+K35
A36: • | B36: Dự án Xesco | E36: =IF(D36>0, F36/D36, 0) | K36: =F36+G36-H36+I36-J36 | L36: ='Thang_10'!L36+D36 | M36: =IF(L36>0, N36/L36, 0) | N36: ='Thang_10'!N36+F36 | O36: ='Thang_10'!O36+G36 | P36: ='Thang_10'!P36+H36 | Q36: ='Thang_10'!Q36+I36-J36 | R36: ='Thang_10'!R36+K36
A37: • | B37: KD sỉ | E37: =IF(D37>0, F37/D37, 0) | K37: =F37+G37-H37+I37-J37 | L37: ='Thang_10'!L37+D37 | M37: =IF(L37>0, N37/L37, 0) | N37: ='Thang_10'!N37+F37 | O37: ='Thang_10'!O37+G37 | P37: ='Thang_10'!P37+H37 | Q37: ='Thang_10'!Q37+I37-J37 | R37: ='Thang_10'!R37+K37
A38: • | B38: KD Online | E38: =IF(D38>0, F38/D38, 0) | K38: =F38+G38-H38+I38-J38 | L38: ='Thang_10'!L38+D38 | M38: =IF(L38>0, N38/L38, 0) | N38: ='Thang_10'!N38+F38 | O38: ='Thang_10'!O38+G38 | P38: ='Thang_10'!P38+H38 | Q38: ='Thang_10'!Q38+I38-J38 | R38: ='Thang_10'!R38+K38
A39: • | B39: KD Thuê máy | E39: =IF(D39>0, F39/D39, 0) | K39: =F39+G39-H39+I39-J39 | L39: ='Thang_10'!L39+D39 | M39: =IF(L39>0, N39/L39, 0) | N39: ='Thang_10'!N39+F39 | O39: ='Thang_10'!O39+G39 | P39: ='Thang_10'!P39+H39 | Q39: ='Thang_10'!Q39+I39-J39 | R39: ='Thang_10'!R39+K39
A40: • | B40: Nội bộ (Công ty) | E40: =IF(D40>0, F40/D40, 0) | K40: =F40+G40-H40+I40-J40 | L40: ='Thang_10'!L40+D40 | M40: =IF(L40>0, N40/L40, 0) | N40: ='Thang_10'!N40+F40 | O40: ='Thang_10'!O40+G40 | P40: ='Thang_10'!P40+H40 | Q40: ='Thang_10'!Q40+I40-J40 | R40: ='Thang_10'!R40+K40
...

Sheet Thang_12
A1: BÁO CÁO KẾT QUẢ HOẠT ĐỘNG KINH DOANH - THÁNG 12/2026
A2: Đơn vị tính: Triệu đồng (Tr.đ) | Tự động cộng dồn lũy kế kế thừa Tháng 11 | Đồng bộ trực tiếp Dashboard VPS Group
A3: TT | B3: NỘI DUNG / ĐƠN VỊ KINH DOANH | C3: VỐN ĐT | D3: PHÁT SINH THÁNG 12/2026 | L3: LŨY KẾ ĐẾN HẾT THÁNG 12/2026
D4: DS | E4: % LG | F4: LG | G4: HT LG | H4: CHI PHÍ | I4: TN KHÁC | J4: CP KHÁC | K4: LNTT | L4: DS | M4: % LG | N4: LG | O4: HT LG | P4: CHI PHÍ | Q4: TN KHÁC | R4: LNTT
A5: I | B5: MIỀN BẮC | C5: 90000 | E5: =IF(D5>0, F5/D5, 0) | K5: =F5+G5-H5+I5-J5 | L5: ='Thang_11'!L5+D5 | M5: =IF(L5>0, N5/L5, 0) | N5: ='Thang_11'!N5+F5 | O5: ='Thang_11'!O5+G5 | P5: ='Thang_11'!P5+H5 | Q5: ='Thang_11'!Q5+I5-J5 | R5: ='Thang_11'!R5+K5
A6: 1 | B6: THH (Tân Hồng Hà) | C6: 50000 | E6: =IF(D6>0, F6/D6, 0) | K6: =F6+G6-H6+I6-J6 | L6: ='Thang_11'!L6+D6 | M6: =IF(L6>0, N6/L6, 0) | N6: ='Thang_11'!N6+F6 | O6: ='Thang_11'!O6+G6 | P6: ='Thang_11'!P6+H6 | Q6: ='Thang_11'!Q6+I6-J6 | R6: ='Thang_11'!R6+K6
A7: a | B7: Khối dịch vụ kỹ thuật | E7: =IF(D7>0, F7/D7, 0) | K7: =F7+G7-H7+I7-J7 | L7: ='Thang_11'!L7+D7 | M7: =IF(L7>0, N7/L7, 0) | N7: ='Thang_11'!N7+F7 | O7: ='Thang_11'!O7+G7 | P7: ='Thang_11'!P7+H7 | Q7: ='Thang_11'!Q7+I7-J7 | R7: ='Thang_11'!R7+K7
A8: a.1 | B8: Tổ Dịch vụ | E8: =IF(D8>0, F8/D8, 0) | K8: =F8+G8-H8+I8-J8 | L8: ='Thang_11'!L8+D8 | M8: =IF(L8>0, N8/L8, 0) | N8: ='Thang_11'!N8+F8 | O8: ='Thang_11'!O8+G8 | P8: ='Thang_11'!P8+H8 | Q8: ='Thang_11'!Q8+I8-J8 | R8: ='Thang_11'!R8+K8
A9: a.2 | B9: Tổ mực in | E9: =IF(D9>0, F9/D9, 0) | K9: =F9+G9-H9+I9-J9 | L9: ='Thang_11'!L9+D9 | M9: =IF(L9>0, N9/L9, 0) | N9: ='Thang_11'!N9+F9 | O9: ='Thang_11'!O9+G9 | P9: ='Thang_11'!P9+H9 | Q9: ='Thang_11'!Q9+I9-J9 | R9: ='Thang_11'!R9+K9
A10: a.3 | B10: Thuê máy | E10: =IF(D10>0, F10/D10, 0) | K10: =F10+G10-H10+I10-J10 | L10: ='Thang_11'!L10+D10 | M10: =IF(L10>0, N10/L10, 0) | N10: ='Thang_11'!N10+F10 | O10: ='Thang_11'!O10+G10 | P10: ='Thang_11'!P10+H10 | Q10: ='Thang_11'!Q10+I10-J10 | R10: ='Thang_11'!R10+K10
A11: a.4 | B11: Metercharge | E11: =IF(D11>0, F11/D11, 0) | K11: =F11+G11-H11+I11-J11 | L11: ='Thang_11'!L11+D11 | M11: =IF(L11>0, N11/L11, 0) | N11: ='Thang_11'!N11+F11 | O11: ='Thang_11'!O11+G11 | P11: ='Thang_11'!P11+H11 | Q11: ='Thang_11'!Q11+I11-J11 | R11: ='Thang_11'!R11+K11
A12: a.5 | B12: Kinh doanh Online | E12: =IF(D12>0, F12/D12, 0) | K12: =F12+G12-H12+I12-J12 | L12: ='Thang_11'!L12+D12 | M12: =IF(L12>0, N12/L12, 0) | N12: ='Thang_11'!N12+F12 | O12: ='Thang_11'!O12+G12 | P12: ='Thang_11'!P12+H12 | Q12: ='Thang_11'!Q12+I12-J12 | R12: ='Thang_11'!R12+K12
A13: b | B13: Kinh doanh tổng hợp | E13: =IF(D13>0, F13/D13, 0) | K13: =F13+G13-H13+I13-J13 | L13: ='Thang_11'!L13+D13 | M13: =IF(L13>0, N13/L13, 0) | N13: ='Thang_11'!N13+F13 | O13: ='Thang_11'!O13+G13 | P13: ='Thang_11'!P13+H13 | Q13: ='Thang_11'!Q13+I13-J13 | R13: ='Thang_11'!R13+K13
A14: c | B14: Kinh doanh bán buôn | E14: =IF(D14>0, F14/D14, 0) | K14: =F14+G14-H14+I14-J14 | L14: ='Thang_11'!L14+D14 | M14: =IF(L14>0, N14/L14, 0) | N14: ='Thang_11'!N14+F14 | O14: ='Thang_11'!O14+G14 | P14: ='Thang_11'!P14+H14 | Q14: ='Thang_11'!Q14+I14-J14 | R14: ='Thang_11'!R14+K14
A15: d | B15: Dự án | E15: =IF(D15>0, F15/D15, 0) | K15: =F15+G15-H15+I15-J15 | L15: ='Thang_11'!L15+D15 | M15: =IF(L15>0, N15/L15, 0) | N15: ='Thang_11'!N15+F15 | O15: ='Thang_11'!O15+G15 | P15: ='Thang_11'!P15+H15 | Q15: ='Thang_11'!Q15+I15-J15 | R15: ='Thang_11'!R15+K15
A16: 2 | B16: Việt | C16: 10000 | E16: =IF(D16>0, F16/D16, 0) | K16: =F16+G16-H16+I16-J16 | L16: ='Thang_11'!L16+D16 | M16: =IF(L16>0, N16/L16, 0) | N16: ='Thang_11'!N16+F16 | O16: ='Thang_11'!O16+G16 | P16: ='Thang_11'!P16+H16 | Q16: ='Thang_11'!Q16+I16-J16 | R16: ='Thang_11'!R16+K16
A17: 2.1 | B17: Thuê máy | E17: =IF(D17>0, F17/D17, 0) | K17: =F17+G17-H17+I17-J17 | L17: ='Thang_11'!L17+D17 | M17: =IF(L17>0, N17/L17, 0) | N17: ='Thang_11'!N17+F17 | O17: ='Thang_11'!O17+G17 | P17: ='Thang_11'!P17+H17 | Q17: ='Thang_11'!Q17+I17-J17 | R17: ='Thang_11'!R17+K17
A18: 2.2 | B18: KDTH | E18: =IF(D18>0, F18/D18, 0) | K18: =F18+G18-H18+I18-J18 | L18: ='Thang_11'!L18+D18 | M18: =IF(L18>0, N18/L18, 0) | N18: ='Thang_11'!N18+F18 | O18: ='Thang_11'!O18+G18 | P18: ='Thang_11'!P18+H18 | Q18: ='Thang_11'!Q18+I18-J18 | R18: ='Thang_11'!R18+K18
A19: 2.3 | B19: KD online | E19: =IF(D19>0, F19/D19, 0) | K19: =F19+G19-H19+I19-J19 | L19: ='Thang_11'!L19+D19 | M19: =IF(L19>0, N19/L19, 0) | N19: ='Thang_11'!N19+F19 | O19: ='Thang_11'!O19+G19 | P19: ='Thang_11'!P19+H19 | Q19: ='Thang_11'!Q19+I19-J19 | R19: ='Thang_11'!R19+K19
A20: 2.4 | B20: Cửa hàng | E20: =IF(D20>0, F20/D20, 0) | K20: =F20+G20-H20+I20-J20 | L20: ='Thang_11'!L20+D20 | M20: =IF(L20>0, N20/L20, 0) | N20: ='Thang_11'!N20+F20 | O20: ='Thang_11'!O20+G20 | P20: ='Thang_11'!P20+H20 | Q20: ='Thang_11'!Q20+I20-J20 | R20: ='Thang_11'!R20+K20
A21: 2.5 | B21: Nội bộ | E21: =IF(D21>0, F21/D21, 0) | K21: =F21+G21-H21+I21-J21 | L21: ='Thang_11'!L21+D21 | M21: =IF(L21>0, N21/L21, 0) | N21: ='Thang_11'!N21+F21 | O21: ='Thang_11'!O21+G21 | P21: ='Thang_11'!P21+H21 | Q21: ='Thang_11'!Q21+I21-J21 | R21: ='Thang_11'!R21+K21
A22: 3 | B22: ITSS | C22: 5000 | E22: =IF(D22>0, F22/D22, 0) | K22: =F22+G22-H22+I22-J22 | L22: ='Thang_11'!L22+D22 | M22: =IF(L22>0, N22/L22, 0) | N22: ='Thang_11'!N22+F22 | O22: ='Thang_11'!O22+G22 | P22: ='Thang_11'!P22+H22 | Q22: ='Thang_11'!Q22+I22-J22 | R22: ='Thang_11'!R22+K22
A23: 4 | B23: CTY VPS | C23: 10000 | E23: =IF(D23>0, F23/D23, 0) | K23: =F23+G23-H23+I23-J23 | L23: ='Thang_11'!L23+D23 | M23: =IF(L23>0, N23/L23, 0) | N23: ='Thang_11'!N23+F23 | O23: ='Thang_11'!O23+G23 | P23: ='Thang_11'!P23+H23 | Q23: ='Thang_11'!Q23+I23-J23 | R23: ='Thang_11'!R23+K23
A24: 4.1 | B24: VP VPS - hoạt động KD | E24: =IF(D24>0, F24/D24, 0) | K24: =F24+G24-H24+I24-J24 | L24: ='Thang_11'!L24+D24 | M24: =IF(L24>0, N24/L24, 0) | N24: ='Thang_11'!N24+F24 | O24: ='Thang_11'!O24+G24 | P24: ='Thang_11'!P24+H24 | Q24: ='Thang_11'!Q24+I24-J24 | R24: ='Thang_11'!R24+K24
A25: • | B25: VPS bán nội bộ | E25: =IF(D25>0, F25/D25, 0) | K25: =F25+G25-H25+I25-J25 | L25: ='Thang_11'!L25+D25 | M25: =IF(L25>0, N25/L25, 0) | N25: ='Thang_11'!N25+F25 | O25: ='Thang_11'!O25+G25 | P25: ='Thang_11'!P25+H25 | Q25: ='Thang_11'!Q25+I25-J25 | R25: ='Thang_11'!R25+K25
A26: • | B26: Xuất khẩu | E26: =IF(D26>0, F26/D26, 0) | K26: =F26+G26-H26+I26-J26 | L26: ='Thang_11'!L26+D26 | M26: =IF(L26>0, N26/L26, 0) | N26: ='Thang_11'!N26+F26 | O26: ='Thang_11'!O26+G26 | P26: ='Thang_11'!P26+H26 | Q26: ='Thang_11'!Q26+I26-J26 | R26: ='Thang_11'!R26+K26
A27: • | B27: Xuất bán trong nước | E27: =IF(D27>0, F27/D27, 0) | K27: =F27+G27-H27+I27-J27 | L27: ='Thang_11'!L27+D27 | M27: =IF(L27>0, N27/L27, 0) | N27: ='Thang_11'!N27+F27 | O27: ='Thang_11'!O27+G27 | P27: ='Thang_11'!P27+H27 | Q27: ='Thang_11'!Q27+I27-J27 | R27: ='Thang_11'!R27+K27
A28: 4.2 | B28: HĐ đầu tư Tài chính | E28: =IF(D28>0, F28/D28, 0) | K28: =F28+G28-H28+I28-J28 | L28: ='Thang_11'!L28+D28 | M28: =IF(L28>0, N28/L28, 0) | N28: ='Thang_11'!N28+F28 | O28: ='Thang_11'!O28+G28 | P28: ='Thang_11'!P28+H28 | Q28: ='Thang_11'!Q28+I28-J28 | R28: ='Thang_11'!R28+K28
A29: 5 | B29: XESCO (Xem Sơn) | C29: 15000 | E29: =IF(D29>0, F29/D29, 0) | K29: =F29+G29-H29+I29-J29 | L29: ='Thang_11'!L29+D29 | M29: =IF(L29>0, N29/L29, 0) | N29: ='Thang_11'!N29+F29 | O29: ='Thang_11'!O29+G29 | P29: ='Thang_11'!P29+H29 | Q29: ='Thang_11'!Q29+I29-J29 | R29: ='Thang_11'!R29+K29
A30: 5.1 | B30: Xesco - KT | E30: =IF(D30>0, F30/D30, 0) | K30: =F30+G30-H30+I30-J30 | L30: ='Thang_11'!L30+D30 | M30: =IF(L30>0, N30/L30, 0) | N30: ='Thang_11'!N30+F30 | O30: ='Thang_11'!O30+G30 | P30: ='Thang_11'!P30+H30 | Q30: ='Thang_11'!Q30+I30-J30 | R30: ='Thang_11'!R30+K30
A31: • | B31: Kỹ thuật thuê máy | E31: =IF(D31>0, F31/D31, 0) | K31: =F31+G31-H31+I31-J31 | L31: ='Thang_11'!L31+D31 | M31: =IF(L31>0, N31/L31, 0) | N31: ='Thang_11'!N31+F31 | O31: ='Thang_11'!O31+G31 | P31: ='Thang_11'!P31+H31 | Q31: ='Thang_11'!Q31+I31-J31 | R31: ='Thang_11'!R31+K31
A32: • | B32: Metercharge | E32: =IF(D32>0, F32/D32, 0) | K32: =F32+G32-H32+I32-J32 | L32: ='Thang_11'!L32+D32 | M32: =IF(L32>0, N32/L32, 0) | N32: ='Thang_11'!N32+F32 | O32: ='Thang_11'!O32+G32 | P32: ='Thang_11'!P32+H32 | Q32: ='Thang_11'!Q32+I32-J32 | R32: ='Thang_11'!R32+K32
A33: • | B33: Dịch vụ kỹ thuật | E33: =IF(D33>0, F33/D33, 0) | K33: =F33+G33-H33+I33-J33 | L33: ='Thang_11'!L33+D33 | M33: =IF(L33>0, N33/L33, 0) | N33: ='Thang_11'!N33+F33 | O33: ='Thang_11'!O33+G33 | P33: ='Thang_11'!P33+H33 | Q33: ='Thang_11'!Q33+I33-J33 | R33: ='Thang_11'!R33+K33
A34: 5.2 | B34: Xesco - KD | E34: =IF(D34>0, F34/D34, 0) | K34: =F34+G34-H34+I34-J34 | L34: ='Thang_11'!L34+D34 | M34: =IF(L34>0, N34/L34, 0) | N34: ='Thang_11'!N34+F34 | O34: ='Thang_11'!O34+G34 | P34: ='Thang_11'!P34+H34 | Q34: ='Thang_11'!Q34+I34-J34 | R34: ='Thang_11'!R34+K34
A35: • | B35: Bán máy lẻ | E35: =IF(D35>0, F35/D35, 0) | K35: =F35+G35-H35+I35-J35 | L35: ='Thang_11'!L35+D35 | M35: =IF(L35>0, N35/L35, 0) | N35: ='Thang_11'!N35+F35 | O35: ='Thang_11'!O35+G35 | P35: ='Thang_11'!P35+H35 | Q35: ='Thang_11'!Q35+I35-J35 | R35: ='Thang_11'!R35+K35
A36: • | B36: Dự án Xesco | E36: =IF(D36>0, F36/D36, 0) | K36: =F36+G36-H36+I36-J36 | L36: ='Thang_11'!L36+D36 | M36: =IF(L36>0, N36/L36, 0) | N36: ='Thang_11'!N36+F36 | O36: ='Thang_11'!O36+G36 | P36: ='Thang_11'!P36+H36 | Q36: ='Thang_11'!Q36+I36-J36 | R36: ='Thang_11'!R36+K36
A37: • | B37: KD sỉ | E37: =IF(D37>0, F37/D37, 0) | K37: =F37+G37-H37+I37-J37 | L37: ='Thang_11'!L37+D37 | M37: =IF(L37>0, N37/L37, 0) | N37: ='Thang_11'!N37+F37 | O37: ='Thang_11'!O37+G37 | P37: ='Thang_11'!P37+H37 | Q37: ='Thang_11'!Q37+I37-J37 | R37: ='Thang_11'!R37+K37
A38: • | B38: KD Online | E38: =IF(D38>0, F38/D38, 0) | K38: =F38+G38-H38+I38-J38 | L38: ='Thang_11'!L38+D38 | M38: =IF(L38>0, N38/L38, 0) | N38: ='Thang_11'!N38+F38 | O38: ='Thang_11'!O38+G38 | P38: ='Thang_11'!P38+H38 | Q38: ='Thang_11'!Q38+I38-J38 | R38: ='Thang_11'!R38+K38
A39: • | B39: KD Thuê máy | E39: =IF(D39>0, F39/D39, 0) | K39: =F39+G39-H39+I39-J39 | L39: ='Thang_11'!L39+D39 | M39: =IF(L39>0, N39/L39, 0) | N39: ='Thang_11'!N39+F39 | O39: ='Thang_11'!O39+G39 | P39: ='Thang_11'!P39+H39 | Q39: ='Thang_11'!Q39+I39-J39 | R39: ='Thang_11'!R39+K39
A40: • | B40: Nội bộ (Công ty) | E40: =IF(D40>0, F40/D40, 0) | K40: =F40+G40-H40+I40-J40 | L40: ='Thang_11'!L40+D40 | M40: =IF(L40>0, N40/L40, 0) | N40: ='Thang_11'!N40+F40 | O40: ='Thang_11'!O40+G40 | P40: ='Thang_11'!P40+H40 | Q40: ='Thang_11'!Q40+I40-J40 | R40: ='Thang_11'!R40+K40
...

Sheet Moc_Luy_Ke_T8_Chot_So
A1: MỐC LŨY KẾ CHỐT SỔ 8 THÁNG ĐẦU NĂM 2026 (VPS GROUP)
A2: Số liệu kiểm toán chính thức làm nền tảng tính toán tự động cho Tháng 9, 10, 11, 12 / 2026
A3: TT | B3: NỘI DUNG | C3: VỐN ĐT | D3: LŨY KẾ DS | E3: % LG | F3: LŨY KẾ LG | G3: HỖ TRỢ LG | H3: CHI PHÍ | I3: TN KHÁC NET | J3: LNTT
A5: I | B5: MIỀN BẮC | C5: 90000 | D5: 154375 | E5: 0.19742834 | F5: 30478 | G5: 343 | H5: 39526 | I5: 9025 | J5: 55
A6: 1 | B6: THH (Tân Hồng Hà) | C6: 50000 | D6: 78197 | E6: 0.20904894 | F6: 16347 | G6: 343 | H6: 13846 | I6: 58 | J6: 2902
A7: a | B7: Khối dịch vụ kỹ thuật | D7: 18382 | E7: 0.35893809 | F7: 6598 | G7: 54 | H7: 6291 | I7: 1 | J7: 362
A8: a.1 | B8: Tổ Dịch vụ | D8: 9304 | E8: 0.33351247 | F8: 3103 | G8: 53
A9: a.2 | B9: Tổ mực in | D9: 2319 | E9: 0.50957309 | F9: 1181.7
A10: a.3 | B10: Thuê máy | D10: 4304 | E10: 0.33104089 | F10: 1424.8
A11: a.4 | B11: Metercharge | D11: 1684 | E11: 0.51840855 | F11: 873
A12: a.5 | B12: Kinh doanh Online | D12: 772 | E12: 0.019559585 | F12: 15.1 | G12: 1
A13: b | B13: Kinh doanh tổng hợp | D13: 14949 | E13: 0.081082347 | F13: 1212.1 | G13: 9 | H13: 1324 | I13: 47 | J13: -55
A14: c | B14: Kinh doanh bán buôn | D14: 30362 | E14: 0.09377182 | F14: 2847.1 | G14: 279 | H14: 2833 | I14: 10 | J14: 303
A15: d | B15: Dự án | D15: 14503 | E15: 0.39235331 | F15: 5690.3 | H15: 3398 | J15: 2292
A16: 2 | B16: Việt | C16: 10000 | D16: 48605 | E16: 0.20582245 | F16: 10004 | H16: 7839 | I16: 0 | J16: 2165
A17: 2.1 | B17: Thuê máy | D17: 12422 | E17: 0.5792143 | F17: 7195
A18: 2.2 | B18: KDTH | D18: 14838 | E18: 0.076492789 | F18: 1135
A19: 2.3 | B19: KD online | D19: 19902 | E19: 0.06225505 | F19: 1239
A20: 2.4 | B20: Cửa hàng | D20: 835 | E20: 0.42634731 | F20: 356
A21: 2.5 | B21: Nội bộ | D21: 608 | E21: 0.12993421 | F21: 79
A22: 3 | B22: ITSS | C22: 5000 | D22: 3555 | E22: 0.36821378 | F22: 1309 | H22: 963 | I22: -4 | J22: 342
A23: 4 | B23: CTY VPS | C23: 10000 | D23: 24017 | E23: 0.11733356 | F23: 2818 | H23: 16878 | I23: 8706 | J23: -5354
A24: 4.1 | B24: VP VPS - hoạt động KD | D24: 24017 | E24: 0.11733356 | F24: 2818 | H24: 5389 | I24: 3159 | J24: 588
A25: • | B25: VPS bán nội bộ | D25: 20532 | E25: 0.12638808 | F25: 2595
A26: • | B26: Xuất khẩu | D26: 2228 | E26: 0.14856373 | F26: 331
A27: • | B27: Xuất bán trong nước | D27: 1258 | E27: -0.085850556 | F27: -108
A28: 4.2 | B28: HĐ đầu tư Tài chính | D28: 0 | E28: 0 | F28: 0 | H28: 11490 | I28: 5547 | J28: -5942
A29: 5 | B29: XESCO (Xem Sơn) | C29: 15000 | D29: 84527 | E29: 0.26839945 | F29: 22687 | H29: 16756 | I29: 364 | J29: 6295
A30: 5.1 | B30: Xesco - KT | D30: 23855 | E30: 0.55426535 | F30: 13222 | H30: 10369 | I30: 94 | J30: 2959
A31: • | B31: Kỹ thuật thuê máy | D31: 11785 | E31: 0.66822232 | F31: 7875 | H31: 6508 | I31: -6 | J31: 1362
A32: • | B32: Metercharge | D32: 2139 | E32: 0.6002805 | F32: 1284 | J32: 1284
A33: • | B33: Dịch vụ kỹ thuật | D33: 9931 | E33: 0.40912295 | F33: 4063 | H33: 3861 | I33: 111 | J33: 313
A34: 5.2 | B34: Xesco - KD | D34: 60672 | E34: 0.15598629 | F34: 9464 | H34: 6387 | I34: 149 | J34: 3336
A35: • | B35: Bán máy lẻ | D35: 3614 | E35: 0.22772551 | F35: 823 | H35: 654 | I35: -3 | J35: 165
A36: • | B36: Dự án Xesco | D36: 3426 | E36: 0.36339755 | F36: 1245 | H36: 131 | I36: -2 | J36: 1112
A37: • | B37: KD sỉ | D37: 27002 | E37: 0.16332124 | F37: 4410 | H37: 3591 | I37: 76 | J37: 895
A38: • | B38: KD Online | D38: 23597 | E38: 0.037377633 | F38: 882 | H38: 792 | I38: -22 | J38: 68
A39: • | B39: KD Thuê máy | D39: 3033 | E39: 0.6937026 | F39: 2104 | H39: 1219 | I39: -3 | J39: 883
A40: • | B40: Nội bộ (Công ty) | E40: 0 | I40: 213 | J40: 213
A41: II | B41: VPS MIỀN TRUNG | C41: 3000 | D41: 12937 | E41: 0.20568911 | F41: 2661 | H41: 1782 | I41: 0 | J41: 880
...

Sheet Huong_Dan_Nhap_Lieu
A1: QUY CHUẨN NHẬP LIỆU BÁO CÁO KẾT QUẢ KINH DOANH (P&L) CÁC ĐƠN VỊ
A2: TẬP ĐOÀN VPS - ÁP DỤNG TỪ THÁNG 09/2026 ĐẾN THÁNG 12/2026
A4: 1. NGUYÊN TẮC NHẬP LIỆU:
A5: - Đơn vị tính thống nhất toàn tập đoàn: Triệu đồng (Tr.đ).
A6: - Các đơn vị THÀNH VIÊN chỉ cần nhập liệu vào CÁC CỘT PHÁT SINH TRONG THÁNG:
A7: + Cột D: Doanh số (DS) phát sinh trong tháng.
A8: + Cột F: Lãi gộp (LG) phát sinh trong tháng.
A9: + Cột G: Hỗ trợ Lãi gộp (HT LG) nếu có.
A10: + Cột H: Tổng chi phí hoạt động phát sinh trong tháng.
A11: + Cột I: Thu nhập khác (nếu có).
A12: + Cột J: Chi phí khác (nếu có).
A13: - CÁC CỘT CÔNG THỨC ĐÃ CÀI ĐẶT TỰ ĐỘNG:
... A29: - Báo cáo phát sinh Tháng 9 sẽ bắt đầu cộng dồn tiếp tục từ mốc 251,839 Tr.đ này.
